Workbook

Sheet 表单1
A1: 文物编号 | B1: 纹饰 | C1: 类型 | D1: 颜色 | E1: 表面风化
A2: 01 | B2: C | C2: 高钾 | D2: 蓝绿 | E2: 无风化
A3: 02 | B3: A | C3: 铅钡 | D3: 浅蓝 | E3: 风化
A4: 03 | B4: A | C4: 高钾 | D4: 蓝绿 | E4: 无风化
A5: 04 | B5: A | C5: 高钾 | D5: 蓝绿 | E5: 无风化
A6: 05 | B6: A | C6: 高钾 | D6: 蓝绿 | E6: 无风化
A7: 06 | B7: A | C7: 高钾 | D7: 蓝绿 | E7: 无风化
A8: 07 | B8: B | C8: 高钾 | D8: 蓝绿 | E8: 风化
A9: 08 | B9: C | C9: 铅钡 | D9: 紫 | E9: 风化
A10: 09 | B10: B | C10: 高钾 | D10: 蓝绿 | E10: 风化
A11: 10 | B11: B | C11: 高钾 | D11: 蓝绿 | E11: 风化
A12: 11 | B12: C | C12: 铅钡 | D12: 浅蓝 | E12: 风化
... A19: 18 | B19: A | C19: 高钾 | D19: 深蓝 | E19: 无风化
A20: 19 | B20: A | C20: 铅钡 | E20: 风化
A21: 20 | B21: A | C21: 铅钡 | D21: 浅蓝 | E21: 无风化
A22: 21 | B22: A | C22: 高钾 | D22: 蓝绿 | E22: 无风化
A23: 22 | B23: B | C23: 高钾 | D23: 蓝绿 | E23: 风化
A24: 23 | B24: A | C24: 铅钡 | D24: 蓝绿 | E24: 风化
A25: 24 | B25: C | C25: 铅钡 | D25: 紫 | E25: 无风化
A26: 25 | B26: C | C26: 铅钡 | D26: 浅蓝 | E26: 风化
A27: 26 | B27: C | C27: 铅钡 | D27: 紫 | E27: 风化
A28: 27 | B28: B | C28: 高钾 | D28: 蓝绿 | E28: 风化
A29: 28 | B29: A | C29: 铅钡 | D29: 浅蓝 | E29: 风化
A30: 29 | B30: A | C30: 铅钡 | D30: 浅蓝 | E30: 风化
A31: 30 | B31: A | C31: 铅钡 | D31: 深蓝 | E31: 无风化
A32: 31 | B32: C | C32: 铅钡 | D32: 紫 | E32: 无风化
... A40: 39 | B40: C | C40: 铅钡 | D40: 深绿 | E40: 风化
A41: 40 | B41: C | C41: 铅钡 | E41: 风化
A42: 41 | B42: C | C42: 铅钡 | D42: 浅绿 | E42: 风化
A43: 42 | B43: A | C43: 铅钡 | D43: 浅蓝 | E43: 风化
A44: 43 | B44: C | C44: 铅钡 | D44: 浅蓝 | E44: 风化
A45: 44 | B45: A | C45: 铅钡 | D45: 浅蓝 | E45: 风化
A46: 45 | B46: A | C46: 铅钡 | D46: 浅蓝 | E46: 无风化
A47: 46 | B47: A | C47: 铅钡 | D47: 浅蓝 | E47: 无风化
A48: 47 | B48: A | C48: 铅钡 | D48: 浅蓝 | E48: 无风化
A49: 48 | B49: A | C49: 铅钡 | E49: 风化
A50: 49 | B50: A | C50: 铅钡 | D50: 黑 | E50: 风化
A51: 50 | B51: A | C51: 铅钡 | D51: 黑 | E51: 风化
A52: 51 | B52: C | C52: 铅钡 | D52: 浅蓝 | E52: 风化
A53: 52 | B53: C | C53: 铅钡 | D53: 浅蓝 | E53: 风化
...

Sheet 表单2
A1: 文物采样点 | B1: 二氧化硅(SiO2) | C1: 氧化钠(Na2O) | D1: 氧化钾(K2O) | E1: 氧化钙(CaO) | F1: 氧化镁(MgO) | G1: 氧化铝(Al2O3) | H1: 氧化铁(Fe2O3) | I1: 氧化铜(CuO) | J1: 氧化铅(PbO) | K1: 氧化钡(BaO) | L1: 五氧化二磷(P2O5) | M1: 氧化锶(SrO) | N1: 氧化锡(SnO2) | O1: 二氧化硫(SO2)
A2: 01 | B2: 69.33 | D2: 9.99 | E2: 6.32 | F2: 0.87 | G2: 3.93 | H2: 1.74 | I2: 3.87 | L2: 1.17 | O2: 0.39
A3: 02 | B3: 36.28 | D3: 1.05 | E3: 2.34 | F3: 1.18 | G3: 5.73 | H3: 1.86 | I3: 0.26 | J3: 47.43 | L3: 3.57 | M3: 0.19
A4: 03部位1 | B4: 87.05 | D4: 5.19 | E4: 2.01 | G4: 4.06 | I4: 0.78 | J4: 0.25 | L4: 0.66
A5: 03部位2 | B5: 61.71 | D5: 12.37 | E5: 5.87 | F5: 1.11 | G5: 5.5 | H5: 2.16 | I5: 5.09 | J5: 1.41 | K5: 2.86 | L5: 0.7 | M5: 0.1
A6: 04 | B6: 65.88 | D6: 9.67 | E6: 7.12 | F6: 1.56 | G6: 6.44 | H6: 2.06 | I6: 2.18 | L6: 0.79 | O6: 0.36
A7: 05 | B7: 61.58 | D7: 10.95 | E7: 7.35 | F7: 1.77 | G7: 7.5 | H7: 2.62 | I7: 3.27 | L7: 0.94 | M7: 0.06 | O7: 0.47
A8: 06部位1 | B8: 67.65 | D8: 7.37 | F8: 1.98 | G8: 11.15 | H8: 2.39 | I8: 2.51 | J8: 0.2 | K8: 1.38 | L8: 4.18 | M8: 0.11
A9: 06部位2 | B9: 59.81 | D9: 7.68 | E9: 5.41 | F9: 1.73 | G9: 10.05 | H9: 6.04 | I9: 2.18 | J9: 0.35 | K9: 0.97 | L9: 4.5 | M9: 0.12
A10: 07 | B10: 92.63 | E10: 1.07 | G10: 1.98 | H10: 0.17 | I10: 3.24 | L10: 0.61
A11: 08 | B11: 20.14 | E11: 1.48 | G11: 1.34 | I11: 10.41 | J11: 28.68 | K11: 31.23 | L11: 3.59 | M11: 0.37 | O11: 2.58
A12: 08严重风化点 | B12: 4.61 | E12: 3.19 | G12: 1.11 | I12: 3.14 | J12: 32.45 | K12: 30.62 | L12: 7.56 | M12: 0.53 | O12: 15.03
A13: 09 | B13: 95.02 | D13: 0.59 | E13: 0.62 | G13: 1.32 | H13: 0.32 | I13: 1.55 | L13: 0.35
A14: 10 | B14: 96.77 | D14: 0.92 | E14: 0.21 | G14: 0.81 | H14: 0.26 | I14: 0.84
A15: 11 | B15: 33.59 | D15: 0.21 | E15: 3.51 | F15: 0.71 | G15: 2.69 | I15: 4.93 | J15: 25.39 | K15: 14.61 | L15: 9.38 | M15: 0.37
A16: 12 | B16: 94.29 | D16: 1.01 | E16: 0.72 | G16: 1.46 | H16: 0.29 | I16: 1.65 | L16: 0.15
A17: 13 | B17: 59.01 | C17: 2.86 | D17: 12.53 | E17: 8.7 | G17: 6.16 | H17: 2.88 | I17: 4.73 | L17: 1.27
A18: 14 | B18: 62.47 | C18: 3.38 | D18: 12.28 | E18: 8.23 | F18: 0.66 | G18: 9.23 | H18: 0.5 | I18: 0.47 | J18: 1.62 | L18: 0.16
A19: 15 | B19: 61.87 | C19: 3.21 | D19: 7.44 | F19: 1.02 | G19: 3.15 | H19: 1.04 | I19: 1.29 | J19: 0.19 | K19: 0 | L19: 0.26
A20: 16 | B20: 65.18 | C20: 2.1 | D20: 14.52 | E20: 8.27 | F20: 0.52 | G20: 6.18 | H20: 0.42 | I20: 1.07 | J20: 0.11 | K20: 0 | M20: 0.04
A21: 17 | B21: 60.71 | C21: 2.12 | D21: 5.71 | F21: 0.85 | H21: 1.04 | I21: 1.09 | J21: 0.19 | K21: 0 | L21: 0.18 | N21: 0
A22: 18 | B22: 79.46 | D22: 9.42 | F22: 1.53 | G22: 3.05 | L22: 1.36 | M22: 0.07 | N22: 2.36
A23: 19 | B23: 29.64 | E23: 2.93 | F23: 0.59 | G23: 3.57 | H23: 1.33 | I23: 3.51 | J23: 42.82 | K23: 5.35 | L23: 8.83 | M23: 0.19
A24: 20 | B24: 37.36 | D24: 0.71 | G24: 5.45 | H24: 1.51 | I24: 4.78 | J24: 9.3 | K24: 23.55 | L24: 5.75
A25: 21 | B25: 76.68 | E25: 4.71 | F25: 1.22 | G25: 6.19 | H25: 2.37 | I25: 3.28 | J25: 1 | K25: 1.97 | L25: 1.1
A26: 22 | B26: 92.35 | D26: 0.74 | E26: 1.66 | F26: 0.64 | G26: 3.5 | H26: 0.35 | I26: 0.55 | L26: 0.21
A27: 23未风化点 | B27: 53.79 | C27: 7.92 | E27: 0.5 | F27: 0.71 | G27: 1.42 | I27: 2.99 | J27: 16.98 | K27: 11.86 | M27: 0.33
A28: 24 | B28: 31.94 | E28: 0.47 | G28: 1.59 | I28: 8.46 | J28: 29.14 | K28: 26.23 | L28: 0.14 | M28: 0.91
A29: 25未风化点 | B29: 50.61 | C29: 2.31 | E29: 0.63 | G29: 1.9 | H29: 1.55 | I29: 1.12 | J29: 31.9 | K29: 6.65 | L29: 0.19 | M29: 0.2
A30: 26 | B30: 19.79 | E30: 1.44 | G30: 0.7 | I30: 10.57 | J30: 29.53 | K30: 32.25 | L30: 3.13 | M30: 0.45 | O30: 1.96
A31: 26严重风化点 | B31: 3.72 | D31: 0.4 | E31: 3.01 | G31: 1.18 | I31: 3.6 | J31: 29.92 | K31: 35.45 | L31: 6.04 | M31: 0.62 | O31: 15.95
A32: 27 | B32: 92.72 | E32: 0.94 | F32: 0.54 | G32: 2.51 | H32: 0.2 | I32: 1.54 | L32: 0.36
A33: 28未风化点 | B33: 68.08 | D33: 0.26 | E33: 1.34 | F33: 1 | G33: 4.7 | H33: 0.41 | I33: 0.33 | J33: 17.14 | K33: 4.04 | L33: 1.04 | M33: 0.12 | N33: 0.23
A34: 29未风化点 | B34: 63.3 | C34: 0.92 | D34: 0.3 | E34: 2.98 | F34: 1.49 | G34: 14.34 | H34: 0.81 | I34: 0.74 | J34: 12.31 | K34: 2.03 | L34: 0.41 | M34: 0.25
A35: 30部位1 | B35: 34.34 | D35: 1.41 | E35: 4.49 | F35: 0.98 | G35: 4.35 | H35: 2.12 | J35: 39.22 | K35: 10.29 | M35: 0.35 | N35: 0.4
A36: 30部位2 | B36: 36.93 | E36: 4.24 | F36: 0.51 | G36: 3.86 | H36: 2.74 | J36: 37.74 | K36: 10.35 | L36: 1.41 | M36: 0.48 | N36: 0.44
A37: 31 | B37: 65.91 | E37: 1.6 | F37: 0.89 | G37: 3.11 | H37: 4.59 | I37: 0.44 | J37: 16.55 | K37: 3.42 | L37: 1.62 | M37: 0.3
A38: 32 | B38: 69.71 | D38: 0.21 | E38: 0.46 | G38: 2.36 | H38: 1 | I38: 0.11 | J38: 19.76 | K38: 4.88 | L38: 0.17
A39: 33 | B39: 75.51 | D39: 0.15 | E39: 0.64 | F39: 1 | G39: 2.35 | I39: 0.47 | J39: 16.16 | K39: 3.55 | L39: 0.13
A40: 34 | B40: 35.78 | D40: 0.25 | E40: 0.78 | G40: 1.62 | H40: 0.47 | I40: 1.51 | J40: 46.55 | K40: 10 | L40: 0.34 | M40: 0.22
...

Sheet 表单3
A1: 文物编号 | B1: 表面风化 | C1: 二氧化硅(SiO2) | D1: 氧化钠(Na2O) | E1: 氧化钾(K2O) | F1: 氧化钙(CaO) | G1: 氧化镁(MgO) | H1: 氧化铝(Al2O3) | I1: 氧化铁(Fe2O3) | J1: 氧化铜(CuO) | K1: 氧化铅(PbO) | L1: 氧化钡(BaO) | M1: 五氧化二磷(P2O5) | N1: 氧化锶(SrO) | O1: 氧化锡(SnO2) | P1: 二氧化硫(SO2)
A2: A1 | B2: 无风化 | C2: 78.45 | F2: 6.08 | G2: 1.86 | H2: 7.23 | I2: 2.15 | J2: 2.11 | M2: 1.06 | N2: 0.03 | P2: 0.51
A3: A2 | B3: 风化 | C3: 37.75 | F3: 7.63 | H3: 2.33 | K3: 34.3 | M3: 14.27
A4: A3 | B4: 无风化 | C4: 31.95 | E4: 1.36 | F4: 7.19 | G4: 0.81 | H4: 2.93 | I4: 7.06 | J4: 0.21 | K4: 39.58 | L4: 4.69 | M4: 2.68 | N4: 0.52
A5: A4 | B5: 无风化 | C5: 35.47 | E5: 0.79 | F5: 2.89 | G5: 1.05 | H5: 7.07 | I5: 6.45 | J5: 0.96 | K5: 24.28 | L5: 8.31 | M5: 8.45 | N5: 0.28
A6: A5 | B6: 风化 | C6: 64.29 | D6: 1.2 | E6: 0.37 | F6: 1.64 | G6: 2.34 | H6: 12.75 | I6: 0.81 | J6: 0.94 | K6: 12.23 | L6: 2.16 | M6: 0.19 | N6: 0.21 | O6: 0.49
A7: A6 | B7: 风化 | C7: 93.17 | E7: 1.35 | F7: 0.64 | G7: 0.21 | H7: 1.52 | I7: 0.27 | J7: 1.73 | M7: 0.21
A8: A7 | B8: 风化 | C8: 90.83 | E8: 0.98 | F8: 1.12 | H8: 5.06 | I8: 0.24 | J8: 1.17 | M8: 0.13 | P8: 0.11
A9: A8 | B9: 无风化 | C9: 51.12 | D9: 0 | E9: 0.23 | F9: 0.89 | G9: 0 | H9: 2.12 | I9: 0 | J9: 9.01 | K9: 21.24 | L9: 11.34 | M9: 1.46 | N9: 0.31 | O9: 0 | P9: 2.26

Sheet 表单1_清洗
A1: 文物编号 | B1: 纹饰 | C1: 类型 | D1: 颜色 | E1: 表面风化 | F1: 清洗颜色 | G1: 风化编码 | H1: 颜色缺失 | I1: 数据检查
A2: 01 | B2: C | C2: 高钾 | D2: 蓝绿 | E2: 无风化 | F2: =IF(D2="","未知",D2) -> 蓝绿 | G2: =IF(E2="风化",1,IF(E2="无风化",0,"检查")) -> 0 | H2: =IF(D2="",1,0) -> 0 | I2: =IF(AND(A2<>"",OR(B2="A",B2="B",B2="C"),OR(C2="高钾",C2="铅钡"),OR(E2="风化",E2="无风化"),COUNTIF($A$2:$A$59,A2)=1),"通过","检查") -> 通过
A3: 02 | B3: A | C3: 铅钡 | D3: 浅蓝 | E3: 风化 | F3: =IF(D3="","未知",D3) -> 浅蓝 | G3: =IF(E3="风化",1,IF(E3="无风化",0,"检查")) -> 1 | H3: =IF(D3="",1,0) -> 0 | I3: =IF(AND(A3<>"",OR(B3="A",B3="B",B3="C"),OR(C3="高钾",C3="铅钡"),OR(E3="风化",E3="无风化"),COUNTIF($A$2:$A$59,A3)=1),"通过","检查") -> 通过
A4: 03 | B4: A | C4: 高钾 | D4: 蓝绿 | E4: 无风化 | F4: =IF(D4="","未知",D4) -> 蓝绿 | G4: =IF(E4="风化",1,IF(E4="无风化",0,"检查")) -> 0 | H4: =IF(D4="",1,0) -> 0 | I4: =IF(AND(A4<>"",OR(B4="A",B4="B",B4="C"),OR(C4="高钾",C4="铅钡"),OR(E4="风化",E4="无风化"),COUNTIF($A$2:$A$59,A4)=1),"通过","检查") -> 通过
A5: 04 | B5: A | C5: 高钾 | D5: 蓝绿 | E5: 无风化 | F5: =IF(D5="","未知",D5) -> 蓝绿 | G5: =IF(E5="风化",1,IF(E5="无风化",0,"检查")) -> 0 | H5: =IF(D5="",1,0) -> 0 | I5: =IF(AND(A5<>"",OR(B5="A",B5="B",B5="C"),OR(C5="高钾",C5="铅钡"),OR(E5="风化",E5="无风化"),COUNTIF($A$2:$A$59,A5)=1),"通过","检查") -> 通过
A6: 05 | B6: A | C6: 高钾 | D6: 蓝绿 | E6: 无风化 | F6: =IF(D6="","未知",D6) -> 蓝绿 | G6: =IF(E6="风化",1,IF(E6="无风化",0,"检查")) -> 0 | H6: =IF(D6="",1,0) -> 0 | I6: =IF(AND(A6<>"",OR(B6="A",B6="B",B6="C"),OR(C6="高钾",C6="铅钡"),OR(E6="风化",E6="无风化"),COUNTIF($A$2:$A$59,A6)=1),"通过","检查") -> 通过
A7: 06 | B7: A | C7: 高钾 | D7: 蓝绿 | E7: 无风化 | F7: =IF(D7="","未知",D7) -> 蓝绿 | G7: =IF(E7="风化",1,IF(E7="无风化",0,"检查")) -> 0 | H7: =IF(D7="",1,0) -> 0 | I7: =IF(AND(A7<>"",OR(B7="A",B7="B",B7="C"),OR(C7="高钾",C7="铅钡"),OR(E7="风化",E7="无风化"),COUNTIF($A$2:$A$59,A7)=1),"通过","检查") -> 通过
A8: 07 | B8: B | C8: 高钾 | D8: 蓝绿 | E8: 风化 | F8: =IF(D8="","未知",D8) -> 蓝绿 | G8: =IF(E8="风化",1,IF(E8="无风化",0,"检查")) -> 1 | H8: =IF(D8="",1,0) -> 0 | I8: =IF(AND(A8<>"",OR(B8="A",B8="B",B8="C"),OR(C8="高钾",C8="铅钡"),OR(E8="风化",E8="无风化"),COUNTIF($A$2:$A$59,A8)=1),"通过","检查") -> 通过
A9: 08 | B9: C | C9: 铅钡 | D9: 紫 | E9: 风化 | F9: =IF(D9="","未知",D9) -> 紫 | G9: =IF(E9="风化",1,IF(E9="无风化",0,"检查")) -> 1 | H9: =IF(D9="",1,0) -> 0 | I9: =IF(AND(A9<>"",OR(B9="A",B9="B",B9="C"),OR(C9="高钾",C9="铅钡"),OR(E9="风化",E9="无风化"),COUNTIF($A$2:$A$59,A9)=1),"通过","检查") -> 通过
A10: 09 | B10: B | C10: 高钾 | D10: 蓝绿 | E10: 风化 | F10: =IF(D10="","未知",D10) -> 蓝绿 | G10: =IF(E10="风化",1,IF(E10="无风化",0,"检查")) -> 1 | H10: =IF(D10="",1,0) -> 0 | I10: =IF(AND(A10<>"",OR(B10="A",B10="B",B10="C"),OR(C10="高钾",C10="铅钡"),OR(E10="风化",E10="无风化"),COUNTIF($A$2:$A$59,A10)=1),"通过","检查") -> 通过
A11: 10 | B11: B | C11: 高钾 | D11: 蓝绿 | E11: 风化 | F11: =IF(D11="","未知",D11) -> 蓝绿 | G11: =IF(E11="风化",1,IF(E11="无风化",0,"检查")) -> 1 | H11: =IF(D11="",1,0) -> 0 | I11: =IF(AND(A11<>"",OR(B11="A",B11="B",B11="C"),OR(C11="高钾",C11="铅钡"),OR(E11="风化",E11="无风化"),COUNTIF($A$2:$A$59,A11)=1),"通过","检查") -> 通过
A12: 11 | B12: C | C12: 铅钡 | D12: 浅蓝 | E12: 风化 | F12: =IF(D12="","未知",D12) -> 浅蓝 | G12: =IF(E12="风化",1,IF(E12="无风化",0,"检查")) -> 1 | H12: =IF(D12="",1,0) -> 0 | I12: =IF(AND(A12<>"",OR(B12="A",B12="B",B12="C"),OR(C12="高钾",C12="铅钡"),OR(E12="风化",E12="无风化"),COUNTIF($A$2:$A$59,A12)=1),"通过","检查") -> 通过
A13: 12 | B13: B | C13: 高钾 | D13: 蓝绿 | E13: 风化 | F13: =IF(D13="","未知",D13) -> 蓝绿 | G13: =IF(E13="风化",1,IF(E13="无风化",0,"检查")) -> 1 | H13: =IF(D13="",1,0) -> 0 | I13: =IF(AND(A13<>"",OR(B13="A",B13="B",B13="C"),OR(C13="高钾",C13="铅钡"),OR(E13="风化",E13="无风化"),COUNTIF($A$2:$A$59,A13)=1),"通过","检查") -> 通过
... A19: 18 | B19: A | C19: 高钾 | D19: 深蓝 | E19: 无风化 | F19: =IF(D19="","未知",D19) -> 深蓝 | G19: =IF(E19="风化",1,IF(E19="无风化",0,"检查")) -> 0 | H19: =IF(D19="",1,0) -> 0 | I19: =IF(AND(A19<>"",OR(B19="A",B19="B",B19="C"),OR(C19="高钾",C19="铅钡"),OR(E19="风化",E19="无风化"),COUNTIF($A$2:$A$59,A19)=1),"通过","检查") -> 通过
A20: 19 | B20: A | C20: 铅钡 | E20: 风化 | F20: =IF(D20="","未知",D20) -> 未知 | G20: =IF(E20="风化",1,IF(E20="无风化",0,"检查")) -> 1 | H20: =IF(D20="",1,0) -> 1 | I20: =IF(AND(A20<>"",OR(B20="A",B20="B",B20="C"),OR(C20="高钾",C20="铅钡"),OR(E20="风化",E20="无风化"),COUNTIF($A$2:$A$59,A20)=1),"通过","检查") -> 通过
A21: 20 | B21: A | C21: 铅钡 | D21: 浅蓝 | E21: 无风化 | F21: =IF(D21="","未知",D21) -> 浅蓝 | G21: =IF(E21="风化",1,IF(E21="无风化",0,"检查")) -> 0 | H21: =IF(D21="",1,0) -> 0 | I21: =IF(AND(A21<>"",OR(B21="A",B21="B",B21="C"),OR(C21="高钾",C21="铅钡"),OR(E21="风化",E21="无风化"),COUNTIF($A$2:$A$59,A21)=1),"通过","检查") -> 通过
A22: 21 | B22: A | C22: 高钾 | D22: 蓝绿 | E22: 无风化 | F22: =IF(D22="","未知",D22) -> 蓝绿 | G22: =IF(E22="风化",1,IF(E22="无风化",0,"检查")) -> 0 | H22: =IF(D22="",1,0) -> 0 | I22: =IF(AND(A22<>"",OR(B22="A",B22="B",B22="C"),OR(C22="高钾",C22="铅钡"),OR(E22="风化",E22="无风化"),COUNTIF($A$2:$A$59,A22)=1),"通过","检查") -> 通过
A23: 22 | B23: B | C23: 高钾 | D23: 蓝绿 | E23: 风化 | F23: =IF(D23="","未知",D23) -> 蓝绿 | G23: =IF(E23="风化",1,IF(E23="无风化",0,"检查")) -> 1 | H23: =IF(D23="",1,0) -> 0 | I23: =IF(AND(A23<>"",OR(B23="A",B23="B",B23="C"),OR(C23="高钾",C23="铅钡"),OR(E23="风化",E23="无风化"),COUNTIF($A$2:$A$59,A23)=1),"通过","检查") -> 通过
A24: 23 | B24: A | C24: 铅钡 | D24: 蓝绿 | E24: 风化 | F24: =IF(D24="","未知",D24) -> 蓝绿 | G24: =IF(E24="风化",1,IF(E24="无风化",0,"检查")) -> 1 | H24: =IF(D24="",1,0) -> 0 | I24: =IF(AND(A24<>"",OR(B24="A",B24="B",B24="C"),OR(C24="高钾",C24="铅钡"),OR(E24="风化",E24="无风化"),COUNTIF($A$2:$A$59,A24)=1),"通过","检查") -> 通过
A25: 24 | B25: C | C25: 铅钡 | D25: 紫 | E25: 无风化 | F25: =IF(D25="","未知",D25) -> 紫 | G25: =IF(E25="风化",1,IF(E25="无风化",0,"检查")) -> 0 | H25: =IF(D25="",1,0) -> 0 | I25: =IF(AND(A25<>"",OR(B25="A",B25="B",B25="C"),OR(C25="高钾",C25="铅钡"),OR(E25="风化",E25="无风化"),COUNTIF($A$2:$A$59,A25)=1),"通过","检查") -> 通过
A26: 25 | B26: C | C26: 铅钡 | D26: 浅蓝 | E26: 风化 | F26: =IF(D26="","未知",D26) -> 浅蓝 | G26: =IF(E26="风化",1,IF(E26="无风化",0,"检查")) -> 1 | H26: =IF(D26="",1,0) -> 0 | I26: =IF(AND(A26<>"",OR(B26="A",B26="B",B26="C"),OR(C26="高钾",C26="铅钡"),OR(E26="风化",E26="无风化"),COUNTIF($A$2:$A$59,A26)=1),"通过","检查") -> 通过
A27: 26 | B27: C | C27: 铅钡 | D27: 紫 | E27: 风化 | F27: =IF(D27="","未知",D27) -> 紫 | G27: =IF(E27="风化",1,IF(E27="无风化",0,"检查")) -> 1 | H27: =IF(D27="",1,0) -> 0 | I27: =IF(AND(A27<>"",OR(B27="A",B27="B",B27="C"),OR(C27="高钾",C27="铅钡"),OR(E27="风化",E27="无风化"),COUNTIF($A$2:$A$59,A27)=1),"通过","检查") -> 通过
A28: 27 | B28: B | C28: 高钾 | D28: 蓝绿 | E28: 风化 | F28: =IF(D28="","未知",D28) -> 蓝绿 | G28: =IF(E28="风化",1,IF(E28="无风化",0,"检查")) -> 1 | H28: =IF(D28="",1,0) -> 0 | I28: =IF(AND(A28<>"",OR(B28="A",B28="B",B28="C"),OR(C28="高钾",C28="铅钡"),OR(E28="风化",E28="无风化"),COUNTIF($A$2:$A$59,A28)=1),"通过","检查") -> 通过
A29: 28 | B29: A | C29: 铅钡 | D29: 浅蓝 | E29: 风化 | F29: =IF(D29="","未知",D29) -> 浅蓝 | G29: =IF(E29="风化",1,IF(E29="无风化",0,"检查")) -> 1 | H29: =IF(D29="",1,0) -> 0 | I29: =IF(AND(A29<>"",OR(B29="A",B29="B",B29="C"),OR(C29="高钾",C29="铅钡"),OR(E29="风化",E29="无风化"),COUNTIF($A$2:$A$59,A29)=1),"通过","检查") -> 通过
A30: 29 | B30: A | C30: 铅钡 | D30: 浅蓝 | E30: 风化 | F30: =IF(D30="","未知",D30) -> 浅蓝 | G30: =IF(E30="风化",1,IF(E30="无风化",0,"检查")) -> 1 | H30: =IF(D30="",1,0) -> 0 | I30: =IF(AND(A30<>"",OR(B30="A",B30="B",B30="C"),OR(C30="高钾",C30="铅钡"),OR(E30="风化",E30="无风化"),COUNTIF($A$2:$A$59,A30)=1),"通过","检查") -> 通过
A31: 30 | B31: A | C31: 铅钡 | D31: 深蓝 | E31: 无风化 | F31: =IF(D31="","未知",D31) -> 深蓝 | G31: =IF(E31="风化",1,IF(E31="无风化",0,"检查")) -> 0 | H31: =IF(D31="",1,0) -> 0 | I31: =IF(AND(A31<>"",OR(B31="A",B31="B",B31="C"),OR(C31="高钾",C31="铅钡"),OR(E31="风化",E31="无风化"),COUNTIF($A$2:$A$59,A31)=1),"通过","检查") -> 通过
A32: 31 | B32: C | C32: 铅钡 | D32: 紫 | E32: 无风化 | F32: =IF(D32="","未知",D32) -> 紫 | G32: =IF(E32="风化",1,IF(E32="无风化",0,"检查")) -> 0 | H32: =IF(D32="",1,0) -> 0 | I32: =IF(AND(A32<>"",OR(B32="A",B32="B",B32="C"),OR(C32="高钾",C32="铅钡"),OR(E32="风化",E32="无风化"),COUNTIF($A$2:$A$59,A32)=1),"通过","检查") -> 通过
... A40: 39 | B40: C | C40: 铅钡 | D40: 深绿 | E40: 风化 | F40: =IF(D40="","未知",D40) -> 深绿 | G40: =IF(E40="风化",1,IF(E40="无风化",0,"检查")) -> 1 | H40: =IF(D40="",1,0) -> 0 | I40: =IF(AND(A40<>"",OR(B40="A",B40="B",B40="C"),OR(C40="高钾",C40="铅钡"),OR(E40="风化",E40="无风化"),COUNTIF($A$2:$A$59,A40)=1),"通过","检查") -> 通过
A41: 40 | B41: C | C41: 铅钡 | E41: 风化 | F41: =IF(D41="","未知",D41) -> 未知 | G41: =IF(E41="风化",1,IF(E41="无风化",0,"检查")) -> 1 | H41: =IF(D41="",1,0) -> 1 | I41: =IF(AND(A41<>"",OR(B41="A",B41="B",B41="C"),OR(C41="高钾",C41="铅钡"),OR(E41="风化",E41="无风化"),COUNTIF($A$2:$A$59,A41)=1),"通过","检查") -> 通过
A42: 41 | B42: C | C42: 铅钡 | D42: 浅绿 | E42: 风化 | F42: =IF(D42="","未知",D42) -> 浅绿 | G42: =IF(E42="风化",1,IF(E42="无风化",0,"检查")) -> 1 | H42: =IF(D42="",1,0) -> 0 | I42: =IF(AND(A42<>"",OR(B42="A",B42="B",B42="C"),OR(C42="高钾",C42="铅钡"),OR(E42="风化",E42="无风化"),COUNTIF($A$2:$A$59,A42)=1),"通过","检查") -> 通过
A43: 42 | B43: A | C43: 铅钡 | D43: 浅蓝 | E43: 风化 | F43: =IF(D43="","未知",D43) -> 浅蓝 | G43: =IF(E43="风化",1,IF(E43="无风化",0,"检查")) -> 1 | H43: =IF(D43="",1,0) -> 0 | I43: =IF(AND(A43<>"",OR(B43="A",B43="B",B43="C"),OR(C43="高钾",C43="铅钡"),OR(E43="风化",E43="无风化"),COUNTIF($A$2:$A$59,A43)=1),"通过","检查") -> 通过
A44: 43 | B44: C | C44: 铅钡 | D44: 浅蓝 | E44: 风化 | F44: =IF(D44="","未知",D44) -> 浅蓝 | G44: =IF(E44="风化",1,IF(E44="无风化",0,"检查")) -> 1 | H44: =IF(D44="",1,0) -> 0 | I44: =IF(AND(A44<>"",OR(B44="A",B44="B",B44="C"),OR(C44="高钾",C44="铅钡"),OR(E44="风化",E44="无风化"),COUNTIF($A$2:$A$59,A44)=1),"通过","检查") -> 通过
A45: 44 | B45: A | C45: 铅钡 | D45: 浅蓝 | E45: 风化 | F45: =IF(D45="","未知",D45) -> 浅蓝 | G45: =IF(E45="风化",1,IF(E45="无风化",0,"检查")) -> 1 | H45: =IF(D45="",1,0) -> 0 | I45: =IF(AND(A45<>"",OR(B45="A",B45="B",B45="C"),OR(C45="高钾",C45="铅钡"),OR(E45="风化",E45="无风化"),COUNTIF($A$2:$A$59,A45)=1),"通过","检查") -> 通过
A46: 45 | B46: A | C46: 铅钡 | D46: 浅蓝 | E46: 无风化 | F46: =IF(D46="","未知",D46) -> 浅蓝 | G46: =IF(E46="风化",1,IF(E46="无风化",0,"检查")) -> 0 | H46: =IF(D46="",1,0) -> 0 | I46: =IF(AND(A46<>"",OR(B46="A",B46="B",B46="C"),OR(C46="高钾",C46="铅钡"),OR(E46="风化",E46="无风化"),COUNTIF($A$2:$A$59,A46)=1),"通过","检查") -> 通过
A47: 46 | B47: A | C47: 铅钡 | D47: 浅蓝 | E47: 无风化 | F47: =IF(D47="","未知",D47) -> 浅蓝 | G47: =IF(E47="风化",1,IF(E47="无风化",0,"检查")) -> 0 | H47: =IF(D47="",1,0) -> 0 | I47: =IF(AND(A47<>"",OR(B47="A",B47="B",B47="C"),OR(C47="高钾",C47="铅钡"),OR(E47="风化",E47="无风化"),COUNTIF($A$2:$A$59,A47)=1),"通过","检查") -> 通过
A48: 47 | B48: A | C48: 铅钡 | D48: 浅蓝 | E48: 无风化 | F48: =IF(D48="","未知",D48) -> 浅蓝 | G48: =IF(E48="风化",1,IF(E48="无风化",0,"检查")) -> 0 | H48: =IF(D48="",1,0) -> 0 | I48: =IF(AND(A48<>"",OR(B48="A",B48="B",B48="C"),OR(C48="高钾",C48="铅钡"),OR(E48="风化",E48="无风化"),COUNTIF($A$2:$A$59,A48)=1),"通过","检查") -> 通过
A49: 48 | B49: A | C49: 铅钡 | E49: 风化 | F49: =IF(D49="","未知",D49) -> 未知 | G49: =IF(E49="风化",1,IF(E49="无风化",0,"检查")) -> 1 | H49: =IF(D49="",1,0) -> 1 | I49: =IF(AND(A49<>"",OR(B49="A",B49="B",B49="C"),OR(C49="高钾",C49="铅钡"),OR(E49="风化",E49="无风化"),COUNTIF($A$2:$A$59,A49)=1),"通过","检查") -> 通过
A50: 49 | B50: A | C50: 铅钡 | D50: 黑 | E50: 风化 | F50: =IF(D50="","未知",D50) -> 黑 | G50: =IF(E50="风化",1,IF(E50="无风化",0,"检查")) -> 1 | H50: =IF(D50="",1,0) -> 0 | I50: =IF(AND(A50<>"",OR(B50="A",B50="B",B50="C"),OR(C50="高钾",C50="铅钡"),OR(E50="风化",E50="无风化"),COUNTIF($A$2:$A$59,A50)=1),"通过","检查") -> 通过
A51: 50 | B51: A | C51: 铅钡 | D51: 黑 | E51: 风化 | F51: =IF(D51="","未知",D51) -> 黑 | G51: =IF(E51="风化",1,IF(E51="无风化",0,"检查")) -> 1 | H51: =IF(D51="",1,0) -> 0 | I51: =IF(AND(A51<>"",OR(B51="A",B51="B",B51="C"),OR(C51="高钾",C51="铅钡"),OR(E51="风化",E51="无风化"),COUNTIF($A$2:$A$59,A51)=1),"通过","检查") -> 通过
A52: 51 | B52: C | C52: 铅钡 | D52: 浅蓝 | E52: 风化 | F52: =IF(D52="","未知",D52) -> 浅蓝 | G52: =IF(E52="风化",1,IF(E52="无风化",0,"检查")) -> 1 | H52: =IF(D52="",1,0) -> 0 | I52: =IF(AND(A52<>"",OR(B52="A",B52="B",B52="C"),OR(C52="高钾",C52="铅钡"),OR(E52="风化",E52="无风化"),COUNTIF($A$2:$A$59,A52)=1),"通过","检查") -> 通过
...

Sheet 表单2_清洗
A1: 文物采样点 | B1: 二氧化硅(SiO2) | C1: 氧化钠(Na2O) | D1: 氧化钾(K2O) | E1: 氧化钙(CaO) | F1: 氧化镁(MgO) | G1: 氧化铝(Al2O3) | H1: 氧化铁(Fe2O3) | I1: 氧化铜(CuO) | J1: 氧化铅(PbO) | K1: 氧化钡(BaO) | L1: 五氧化二磷(P2O5) | M1: 氧化锶(SrO) | N1: 氧化锡(SnO2) | O1: 二氧化硫(SO2) | P1: 文物编号 | Q1: 采样点类型 | R1: 玻璃类型 | S1: 文物整体风化 | T1: 采样点实际风化 | U1: 原始成分总和 | V1: 数据有效性 | W1: 未检出成分数 | X1: 二氧化硅(SiO2)_归一化 | Y1: 氧化钠(Na2O)_归一化 | Z1: 氧化钾(K2O)_归一化 | AA1: 氧化钙(CaO)_归一化 | AB1: 氧化镁(MgO)_归一化 | AC1: 氧化铝(Al2O3)_归一化 | AD1: 氧化铁(Fe2O3)_归一化 | AE1: 氧化铜(CuO)_归一化 | AF1: 氧化铅(PbO)_归一化 | AG1: 氧化钡(BaO)_归一化 | AH1: 五氧化二磷(P2O5)_归一化 | AI1: 氧化锶(SrO)_归一化 | AJ1: 氧化锡(SnO2)_归一化 | AK1: 二氧化硫(SO2)_归一化 | AL1: 归一化合计
A2: 01 | B2: 69.33 | D2: 9.99 | E2: 6.32 | F2: 0.87 | G2: 3.93 | H2: 1.74 | I2: 3.87 | L2: 1.17 | O2: 0.39 | P2: 01 | Q2: =IF(ISNUMBER(SEARCH("未风化点",A2)),"未风化点",IF(ISNUMBER(SEARCH("严重风化点",A2)),"严重风化点",IF(ISNUMBER(SEARCH("部位",A2)),"不同部位","普通采样点"))) -> 普通采样点 | R2: =VLOOKUP(P2,表单1_清洗!$A$2:$E$59,3,FALSE) -> 高钾 | S2: =VLOOKUP(P2,表单1_清洗!$A$2:$E$59,5,FALSE) -> 无风化 | T2: =IF(ISNUMBER(SEARCH("未风化点",A2)),"无风化",IF(ISNUMBER(SEARCH("严重风化点",A2)),"风化",S2)) -> 无风化 | U2: =SUM(B2:O2) -> 97.61 | V2: =IF(AND(U2>=85,U2<=105),"有效","无效") -> 有效 | W2: =COUNTBLANK(B2:O2)+COUNTIF(B2:O2,0) -> 5 | X2: =IF($V2="无效","",IF(B2="",0,B2/$U2*100)) -> 71.027559 | Y2: =IF($V2="无效","",IF(C2="",0,C2/$U2*100)) -> 0 | Z2: =IF($V2="无效","",IF(D2="",0,D2/$U2*100)) -> 10.234607 | AA2: =IF($V2="无效","",IF(E2="",0,E2/$U2*100)) -> 6.4747464 | AB2: =IF($V2="无效","",IF(F2="",0,F2/$U2*100)) -> 0.89130212 | AC2: =IF($V2="无效","",IF(G2="",0,G2/$U2*100)) -> 4.0262268 | AD2: =IF($V2="无效","",IF(H2="",0,H2/$U2*100)) -> 1.7826042 | AE2: =IF($V2="无效","",IF(I2="",0,I2/$U2*100)) -> 3.9647577 | ... AK2: =IF($V2="无效","",IF(O2="",0,O2/$U2*100)) -> 0.39954923 | AL2: =IF(V2="有效",SUM(X2:AK2),"") -> 100
A3: 02 | B3: 36.28 | D3: 1.05 | E3: 2.34 | F3: 1.18 | G3: 5.73 | H3: 1.86 | I3: 0.26 | J3: 47.43 | L3: 3.57 | M3: 0.19 | P3: 02 | Q3: =IF(ISNUMBER(SEARCH("未风化点",A3)),"未风化点",IF(ISNUMBER(SEARCH("严重风化点",A3)),"严重风化点",IF(ISNUMBER(SEARCH("部位",A3)),"不同部位","普通采样点"))) -> 普通采样点 | R3: =VLOOKUP(P3,表单1_清洗!$A$2:$E$59,3,FALSE) -> 铅钡 | S3: =VLOOKUP(P3,表单1_清洗!$A$2:$E$59,5,FALSE) -> 风化 | T3: =IF(ISNUMBER(SEARCH("未风化点",A3)),"无风化",IF(ISNUMBER(SEARCH("严重风化点",A3)),"风化",S3)) -> 风化 | U3: =SUM(B3:O3) -> 99.89 | V3: =IF(AND(U3>=85,U3<=105),"有效","无效") -> 有效 | W3: =COUNTBLANK(B3:O3)+COUNTIF(B3:O3,0) -> 4 | X3: =IF($V3="无效","",IF(B3="",0,B3/$U3*100)) -> 36.319952 | Y3: =IF($V3="无效","",IF(C3="",0,C3/$U3*100)) -> 0 | Z3: =IF($V3="无效","",IF(D3="",0,D3/$U3*100)) -> 1.0511563 | AA3: =IF($V3="无效","",IF(E3="",0,E3/$U3*100)) -> 2.3425768 | AB3: =IF($V3="无效","",IF(F3="",0,F3/$U3*100)) -> 1.1812994 | AC3: =IF($V3="无效","",IF(G3="",0,G3/$U3*100)) -> 5.7363099 | AD3: =IF($V3="无效","",IF(H3="",0,H3/$U3*100)) -> 1.8620483 | AE3: =IF($V3="无效","",IF(I3="",0,I3/$U3*100)) -> 0.26028631 | ... AK3: =IF($V3="无效","",IF(O3="",0,O3/$U3*100)) -> 0 | AL3: =IF(V3="有效",SUM(X3:AK3),"") -> 100
A4: 03部位1 | B4: 87.05 | D4: 5.19 | E4: 2.01 | G4: 4.06 | I4: 0.78 | J4: 0.25 | L4: 0.66 | P4: 03 | Q4: =IF(ISNUMBER(SEARCH("未风化点",A4)),"未风化点",IF(ISNUMBER(SEARCH("严重风化点",A4)),"严重风化点",IF(ISNUMBER(SEARCH("部位",A4)),"不同部位","普通采样点"))) -> 不同部位 | R4: =VLOOKUP(P4,表单1_清洗!$A$2:$E$59,3,FALSE) -> 高钾 | S4: =VLOOKUP(P4,表单1_清洗!$A$2:$E$59,5,FALSE) -> 无风化 | T4: =IF(ISNUMBER(SEARCH("未风化点",A4)),"无风化",IF(ISNUMBER(SEARCH("严重风化点",A4)),"风化",S4)) -> 无风化 | U4: =SUM(B4:O4) -> 100 | V4: =IF(AND(U4>=85,U4<=105),"有效","无效") -> 有效 | W4: =COUNTBLANK(B4:O4)+COUNTIF(B4:O4,0) -> 7 | X4: =IF($V4="无效","",IF(B4="",0,B4/$U4*100)) -> 87.05 | Y4: =IF($V4="无效","",IF(C4="",0,C4/$U4*100)) -> 0 | Z4: =IF($V4="无效","",IF(D4="",0,D4/$U4*100)) -> 5.19 | AA4: =IF($V4="无效","",IF(E4="",0,E4/$U4*100)) -> 2.01 | AB4: =IF($V4="无效","",IF(F4="",0,F4/$U4*100)) -> 0 | AC4: =IF($V4="无效","",IF(G4="",0,G4/$U4*100)) -> 4.06 | AD4: =IF($V4="无效","",IF(H4="",0,H4/$U4*100)) -> 0 | AE4: =IF($V4="无效","",IF(I4="",0,I4/$U4*100)) -> 0.78 | ... AK4: =IF($V4="无效","",IF(O4="",0,O4/$U4*100)) -> 0 | AL4: =IF(V4="有效",SUM(X4:AK4),"") -> 100
A5: 03部位2 | B5: 61.71 | D5: 12.37 | E5: 5.87 | F5: 1.11 | G5: 5.5 | H5: 2.16 | I5: 5.09 | J5: 1.41 | K5: 2.86 | L5: 0.7 | M5: 0.1 | P5: 03 | Q5: =IF(ISNUMBER(SEARCH("未风化点",A5)),"未风化点",IF(ISNUMBER(SEARCH("严重风化点",A5)),"严重风化点",IF(ISNUMBER(SEARCH("部位",A5)),"不同部位","普通采样点"))) -> 不同部位 | R5: =VLOOKUP(P5,表单1_清洗!$A$2:$E$59,3,FALSE) -> 高钾 | S5: =VLOOKUP(P5,表单1_清洗!$A$2:$E$59,5,FALSE) -> 无风化 | T5: =IF(ISNUMBER(SEARCH("未风化点",A5)),"无风化",IF(ISNUMBER(SEARCH("严重风化点",A5)),"风化",S5)) -> 无风化 | U5: =SUM(B5:O5) -> 98.88 | V5: =IF(AND(U5>=85,U5<=105),"有效","无效") -> 有效 | W5: =COUNTBLANK(B5:O5)+COUNTIF(B5:O5,0) -> 3 | X5: =IF($V5="无效","",IF(B5="",0,B5/$U5*100)) -> 62.408981 | Y5: =IF($V5="无效","",IF(C5="",0,C5/$U5*100)) -> 0 | Z5: =IF($V5="无效","",IF(D5="",0,D5/$U5*100)) -> 12.510113 | AA5: =IF($V5="无效","",IF(E5="",0,E5/$U5*100)) -> 5.9364887 | AB5: =IF($V5="无效","",IF(F5="",0,F5/$U5*100)) -> 1.1225728 | AC5: =IF($V5="无效","",IF(G5="",0,G5/$U5*100)) -> 5.5622977 | AD5: =IF($V5="无效","",IF(H5="",0,H5/$U5*100)) -> 2.184466 | AE5: =IF($V5="无效","",IF(I5="",0,I5/$U5*100)) -> 5.1476537 | ... AK5: =IF($V5="无效","",IF(O5="",0,O5/$U5*100)) -> 0 | AL5: =IF(V5="有效",SUM(X5:AK5),"") -> 100
A6: 04 | B6: 65.88 | D6: 9.67 | E6: 7.12 | F6: 1.56 | G6: 6.44 | H6: 2.06 | I6: 2.18 | L6: 0.79 | O6: 0.36 | P6: 04 | Q6: =IF(ISNUMBER(SEARCH("未风化点",A6)),"未风化点",IF(ISNUMBER(SEARCH("严重风化点",A6)),"严重风化点",IF(ISNUMBER(SEARCH("部位",A6)),"不同部位","普通采样点"))) -> 普通采样点 | R6: =VLOOKUP(P6,表单1_清洗!$A$2:$E$59,3,FALSE) -> 高钾 | S6: =VLOOKUP(P6,表单1_清洗!$A$2:$E$59,5,FALSE) -> 无风化 | T6: =IF(ISNUMBER(SEARCH("未风化点",A6)),"无风化",IF(ISNUMBER(SEARCH("严重风化点",A6)),"风化",S6)) -> 无风化 | U6: =SUM(B6:O6) -> 96.06 | V6: =IF(AND(U6>=85,U6<=105),"有效","无效") -> 有效 | W6: =COUNTBLANK(B6:O6)+COUNTIF(B6:O6,0) -> 5 | X6: =IF($V6="无效","",IF(B6="",0,B6/$U6*100)) -> 68.582136 | Y6: =IF($V6="无效","",IF(C6="",0,C6/$U6*100)) -> 0 | Z6: =IF($V6="无效","",IF(D6="",0,D6/$U6*100)) -> 10.066625 | AA6: =IF($V6="无效","",IF(E6="",0,E6/$U6*100)) -> 7.4120341 | AB6: =IF($V6="无效","",IF(F6="",0,F6/$U6*100)) -> 1.623985 | AC6: =IF($V6="无效","",IF(G6="",0,G6/$U6*100)) -> 6.7041432 | AD6: =IF($V6="无效","",IF(H6="",0,H6/$U6*100)) -> 2.144493 | AE6: =IF($V6="无效","",IF(I6="",0,I6/$U6*100)) -> 2.2694149 | ... AK6: =IF($V6="无效","",IF(O6="",0,O6/$U6*100)) -> 0.37476577 | AL6: =IF(V6="有效",SUM(X6:AK6),"") -> 100
A7: 05 | B7: 61.58 | D7: 10.95 | E7: 7.35 | F7: 1.77 | G7: 7.5 | H7: 2.62 | I7: 3.27 | L7: 0.94 | M7: 0.06 | O7: 0.47 | P7: 05 | Q7: =IF(ISNUMBER(SEARCH("未风化点",A7)),"未风化点",IF(ISNUMBER(SEARCH("严重风化点",A7)),"严重风化点",IF(ISNUMBER(SEARCH("部位",A7)),"不同部位","普通采样点"))) -> 普通采样点 | R7: =VLOOKUP(P7,表单1_清洗!$A$2:$E$59,3,FALSE) -> 高钾 | S7: =VLOOKUP(P7,表单1_清洗!$A$2:$E$59,5,FALSE) -> 无风化 | T7: =IF(ISNUMBER(SEARCH("未风化点",A7)),"无风化",IF(ISNUMBER(SEARCH("严重风化点",A7)),"风化",S7)) -> 无风化 | U7: =SUM(B7:O7) -> 96.51 | V7: =IF(AND(U7>=85,U7<=105),"有效","无效") -> 有效 | W7: =COUNTBLANK(B7:O7)+COUNTIF(B7:O7,0) -> 4 | X7: =IF($V7="无效","",IF(B7="",0,B7/$U7*100)) -> 63.806859 | Y7: =IF($V7="无效","",IF(C7="",0,C7/$U7*100)) -> 0 | Z7: =IF($V7="无效","",IF(D7="",0,D7/$U7*100)) -> 11.345975 | AA7: =IF($V7="无效","",IF(E7="",0,E7/$U7*100)) -> 7.6157911 | AB7: =IF($V7="无效","",IF(F7="",0,F7/$U7*100)) -> 1.8340068 | AC7: =IF($V7="无效","",IF(G7="",0,G7/$U7*100)) -> 7.7712154 | AD7: =IF($V7="无效","",IF(H7="",0,H7/$U7*100)) -> 2.7147446 | AE7: =IF($V7="无效","",IF(I7="",0,I7/$U7*100)) -> 3.3882499 | ... AK7: =IF($V7="无效","",IF(O7="",0,O7/$U7*100)) -> 0.48699617 | AL7: =IF(V7="有效",SUM(X7:AK7),"") -> 100
A8: 06部位1 | B8: 67.65 | D8: 7.37 | F8: 1.98 | G8: 11.15 | H8: 2.39 | I8: 2.51 | J8: 0.2 | K8: 1.38 | L8: 4.18 | M8: 0.11 | P8: 06 | Q8: =IF(ISNUMBER(SEARCH("未风化点",A8)),"未风化点",IF(ISNUMBER(SEARCH("严重风化点",A8)),"严重风化点",IF(ISNUMBER(SEARCH("部位",A8)),"不同部位","普通采样点"))) -> 不同部位 | R8: =VLOOKUP(P8,表单1_清洗!$A$2:$E$59,3,FALSE) -> 高钾 | S8: =VLOOKUP(P8,表单1_清洗!$A$2:$E$59,5,FALSE) -> 无风化 | T8: =IF(ISNUMBER(SEARCH("未风化点",A8)),"无风化",IF(ISNUMBER(SEARCH("严重风化点",A8)),"风化",S8)) -> 无风化 | U8: =SUM(B8:O8) -> 98.92 | V8: =IF(AND(U8>=85,U8<=105),"有效","无效") -> 有效 | W8: =COUNTBLANK(B8:O8)+COUNTIF(B8:O8,0) -> 4 | X8: =IF($V8="无效","",IF(B8="",0,B8/$U8*100)) -> 68.388597 | Y8: =IF($V8="无效","",IF(C8="",0,C8/$U8*100)) -> 0 | Z8: =IF($V8="无效","",IF(D8="",0,D8/$U8*100)) -> 7.450465 | AA8: =IF($V8="无效","",IF(E8="",0,E8/$U8*100)) -> 0 | AB8: =IF($V8="无效","",IF(F8="",0,F8/$U8*100)) -> 2.0016175 | AC8: =IF($V8="无效","",IF(G8="",0,G8/$U8*100)) -> 11.271735 | AD8: =IF($V8="无效","",IF(H8="",0,H8/$U8*100)) -> 2.4160938 | AE8: =IF($V8="无效","",IF(I8="",0,I8/$U8*100)) -> 2.537404 | ... AK8: =IF($V8="无效","",IF(O8="",0,O8/$U8*100)) -> 0 | AL8: =IF(V8="有效",SUM(X8:AK8),"") -> 100
A9: 06部位2 | B9: 59.81 | D9: 7.68 | E9: 5.41 | F9: 1.73 | G9: 10.05 | H9: 6.04 | I9: 2.18 | J9: 0.35 | K9: 0.97 | L9: 4.5 | M9: 0.12 | P9: 06 | Q9: =IF(ISNUMBER(SEARCH("未风化点",A9)),"未风化点",IF(ISNUMBER(SEARCH("严重风化点",A9)),"严重风化点",IF(ISNUMBER(SEARCH("部位",A9)),"不同部位","普通采样点"))) -> 不同部位 | R9: =VLOOKUP(P9,表单1_清洗!$A$2:$E$59,3,FALSE) -> 高钾 | S9: =VLOOKUP(P9,表单1_清洗!$A$2:$E$59,5,FALSE) -> 无风化 | T9: =IF(ISNUMBER(SEARCH("未风化点",A9)),"无风化",IF(ISNUMBER(SEARCH("严重风化点",A9)),"风化",S9)) -> 无风化 | U9: =SUM(B9:O9) -> 98.84 | V9: =IF(AND(U9>=85,U9<=105),"有效","无效") -> 有效 | W9: =COUNTBLANK(B9:O9)+COUNTIF(B9:O9,0) -> 3 | X9: =IF($V9="无效","",IF(B9="",0,B9/$U9*100)) -> 60.511938 | Y9: =IF($V9="无效","",IF(C9="",0,C9/$U9*100)) -> 0 | Z9: =IF($V9="无效","",IF(D9="",0,D9/$U9*100)) -> 7.7701335 | AA9: =IF($V9="无效","",IF(E9="",0,E9/$U9*100)) -> 5.4734925 | AB9: =IF($V9="无效","",IF(F9="",0,F9/$U9*100)) -> 1.7503035 | AC9: =IF($V9="无效","",IF(G9="",0,G9/$U9*100)) -> 10.167948 | AD9: =IF($V9="无效","",IF(H9="",0,H9/$U9*100)) -> 6.1108863 | AE9: =IF($V9="无效","",IF(I9="",0,I9/$U9*100)) -> 2.2055848 | ... AK9: =IF($V9="无效","",IF(O9="",0,O9/$U9*100)) -> 0 | AL9: =IF(V9="有效",SUM(X9:AK9),"") -> 100
A10: 07 | B10: 92.63 | E10: 1.07 | G10: 1.98 | H10: 0.17 | I10: 3.24 | L10: 0.61 | P10: 07 | Q10: =IF(ISNUMBER(SEARCH("未风化点",A10)),"未风化点",IF(ISNUMBER(SEARCH("严重风化点",A10)),"严重风化点",IF(ISNUMBER(SEARCH("部位",A10)),"不同部位","普通采样点"))) -> 普通采样点 | R10: =VLOOKUP(P10,表单1_清洗!$A$2:$E$59,3,FALSE) -> 高钾 | S10: =VLOOKUP(P10,表单1_清洗!$A$2:$E$59,5,FALSE) -> 风化 | T10: =IF(ISNUMBER(SEARCH("未风化点",A10)),"无风化",IF(ISNUMBER(SEARCH("严重风化点",A10)),"风化",S10)) -> 风化 | U10: =SUM(B10:O10) -> 99.7 | V10: =IF(AND(U10>=85,U10<=105),"有效","无效") -> 有效 | W10: =COUNTBLANK(B10:O10)+COUNTIF(B10:O10,0) -> 8 | X10: =IF($V10="无效","",IF(B10="",0,B10/$U10*100)) -> 92.908726 | Y10: =IF($V10="无效","",IF(C10="",0,C10/$U10*100)) -> 0 | Z10: =IF($V10="无效","",IF(D10="",0,D10/$U10*100)) -> 0 | AA10: =IF($V10="无效","",IF(E10="",0,E10/$U10*100)) -> 1.0732197 | AB10: =IF($V10="无效","",IF(F10="",0,F10/$U10*100)) -> 0 | AC10: =IF($V10="无效","",IF(G10="",0,G10/$U10*100)) -> 1.9859579 | AD10: =IF($V10="无效","",IF(H10="",0,H10/$U10*100)) -> 0.17051153 | AE10: =IF($V10="无效","",IF(I10="",0,I10/$U10*100)) -> 3.2497492 | ... AK10: =IF($V10="无效","",IF(O10="",0,O10/$U10*100)) -> 0 | AL10: =IF(V10="有效",SUM(X10:AK10),"") -> 100
A11: 08 | B11: 20.14 | E11: 1.48 | G11: 1.34 | I11: 10.41 | J11: 28.68 | K11: 31.23 | L11: 3.59 | M11: 0.37 | O11: 2.58 | P11: 08 | Q11: =IF(ISNUMBER(SEARCH("未风化点",A11)),"未风化点",IF(ISNUMBER(SEARCH("严重风化点",A11)),"严重风化点",IF(ISNUMBER(SEARCH("部位",A11)),"不同部位","普通采样点"))) -> 普通采样点 | R11: =VLOOKUP(P11,表单1_清洗!$A$2:$E$59,3,FALSE) -> 铅钡 | S11: =VLOOKUP(P11,表单1_清洗!$A$2:$E$59,5,FALSE) -> 风化 | T11: =IF(ISNUMBER(SEARCH("未风化点",A11)),"无风化",IF(ISNUMBER(SEARCH("严重风化点",A11)),"风化",S11)) -> 风化 | U11: =SUM(B11:O11) -> 99.82 | V11: =IF(AND(U11>=85,U11<=105),"有效","无效") -> 有效 | W11: =COUNTBLANK(B11:O11)+COUNTIF(B11:O11,0) -> 5 | X11: =IF($V11="无效","",IF(B11="",0,B11/$U11*100)) -> 20.176317 | Y11: =IF($V11="无效","",IF(C11="",0,C11/$U11*100)) -> 0 | Z11: =IF($V11="无效","",IF(D11="",0,D11/$U11*100)) -> 0 | AA11: =IF($V11="无效","",IF(E11="",0,E11/$U11*100)) -> 1.4826688 | AB11: =IF($V11="无效","",IF(F11="",0,F11/$U11*100)) -> 0 | AC11: =IF($V11="无效","",IF(G11="",0,G11/$U11*100)) -> 1.3424163 | AD11: =IF($V11="无效","",IF(H11="",0,H11/$U11*100)) -> 0 | AE11: =IF($V11="无效","",IF(I11="",0,I11/$U11*100)) -> 10.428772 | ... AK11: =IF($V11="无效","",IF(O11="",0,O11/$U11*100)) -> 2.5846524 | AL11: =IF(V11="有效",SUM(X11:AK11),"") -> 100
A12: 08严重风化点 | B12: 4.61 | E12: 3.19 | G12: 1.11 | I12: 3.14 | J12: 32.45 | K12: 30.62 | L12: 7.56 | M12: 0.53 | O12: 15.03 | P12: 08 | Q12: =IF(ISNUMBER(SEARCH("未风化点",A12)),"未风化点",IF(ISNUMBER(SEARCH("严重风化点",A12)),"严重风化点",IF(ISNUMBER(SEARCH("部位",A12)),"不同部位","普通采样点"))) -> 严重风化点 | R12: =VLOOKUP(P12,表单1_清洗!$A$2:$E$59,3,FALSE) -> 铅钡 | S12: =VLOOKUP(P12,表单1_清洗!$A$2:$E$59,5,FALSE) -> 风化 | T12: =IF(ISNUMBER(SEARCH("未风化点",A12)),"无风化",IF(ISNUMBER(SEARCH("严重风化点",A12)),"风化",S12)) -> 风化 | U12: =SUM(B12:O12) -> 98.24 | V12: =IF(AND(U12>=85,U12<=105),"有效","无效") -> 有效 | W12: =COUNTBLANK(B12:O12)+COUNTIF(B12:O12,0) -> 5 | X12: =IF($V12="无效","",IF(B12="",0,B12/$U12*100)) -> 4.6925896 | Y12: =IF($V12="无效","",IF(C12="",0,C12/$U12*100)) -> 0 | Z12: =IF($V12="无效","",IF(D12="",0,D12/$U12*100)) -> 0 | AA12: =IF($V12="无效","",IF(E12="",0,E12/$U12*100)) -> 3.2471498 | AB12: =IF($V12="无效","",IF(F12="",0,F12/$U12*100)) -> 0 | AC12: =IF($V12="无效","",IF(G12="",0,G12/$U12*100)) -> 1.129886 | AD12: =IF($V12="无效","",IF(H12="",0,H12/$U12*100)) -> 0 | AE12: =IF($V12="无效","",IF(I12="",0,I12/$U12*100)) -> 3.1962541 | ... AK12: =IF($V12="无效","",IF(O12="",0,O12/$U12*100)) -> 15.299267 | AL12: =IF(V12="有效",SUM(X12:AK12),"") -> 100
A13: 09 | B13: 95.02 | D13: 0.59 | E13: 0.62 | G13: 1.32 | H13: 0.32 | I13: 1.55 | L13: 0.35 | P13: 09 | Q13: =IF(ISNUMBER(SEARCH("未风化点",A13)),"未风化点",IF(ISNUMBER(SEARCH("严重风化点",A13)),"严重风化点",IF(ISNUMBER(SEARCH("部位",A13)),"不同部位","普通采样点"))) -> 普通采样点 | R13: =VLOOKUP(P13,表单1_清洗!$A$2:$E$59,3,FALSE) -> 高钾 | S13: =VLOOKUP(P13,表单1_清洗!$A$2:$E$59,5,FALSE) -> 风化 | T13: =IF(ISNUMBER(SEARCH("未风化点",A13)),"无风化",IF(ISNUMBER(SEARCH("严重风化点",A13)),"风化",S13)) -> 风化 | U13: =SUM(B13:O13) -> 99.77 | V13: =IF(AND(U13>=85,U13<=105),"有效","无效") -> 有效 | W13: =COUNTBLANK(B13:O13)+COUNTIF(B13:O13,0) -> 7 | X13: =IF($V13="无效","",IF(B13="",0,B13/$U13*100)) -> 95.23905 | Y13: =IF($V13="无效","",IF(C13="",0,C13/$U13*100)) -> 0 | Z13: =IF($V13="无效","",IF(D13="",0,D13/$U13*100)) -> 0.59136013 | AA13: =IF($V13="无效","",IF(E13="",0,E13/$U13*100)) -> 0.62142929 | AB13: =IF($V13="无效","",IF(F13="",0,F13/$U13*100)) -> 0 | AC13: =IF($V13="无效","",IF(G13="",0,G13/$U13*100)) -> 1.323043 | AD13: =IF($V13="无效","",IF(H13="",0,H13/$U13*100)) -> 0.3207377 | AE13: =IF($V13="无效","",IF(I13="",0,I13/$U13*100)) -> 1.5535732 | ... AK13: =IF($V13="无效","",IF(O13="",0,O13/$U13*100)) -> 0 | AL13: =IF(V13="有效",SUM(X13:AK13),"") -> 100
A14: 10 | B14: 96.77 | D14: 0.92 | E14: 0.21 | G14: 0.81 | H14: 0.26 | I14: 0.84 | P14: 10 | Q14: =IF(ISNUMBER(SEARCH("未风化点",A14)),"未风化点",IF(ISNUMBER(SEARCH("严重风化点",A14)),"严重风化点",IF(ISNUMBER(SEARCH("部位",A14)),"不同部位","普通采样点"))) -> 普通采样点 | R14: =VLOOKUP(P14,表单1_清洗!$A$2:$E$59,3,FALSE) -> 高钾 | S14: =VLOOKUP(P14,表单1_清洗!$A$2:$E$59,5,FALSE) -> 风化 | T14: =IF(ISNUMBER(SEARCH("未风化点",A14)),"无风化",IF(ISNUMBER(SEARCH("严重风化点",A14)),"风化",S14)) -> 风化 | U14: =SUM(B14:O14) -> 99.81 | V14: =IF(AND(U14>=85,U14<=105),"有效","无效") -> 有效 | W14: =COUNTBLANK(B14:O14)+COUNTIF(B14:O14,0) -> 8 | X14: =IF($V14="无效","",IF(B14="",0,B14/$U14*100)) -> 96.954213 | Y14: =IF($V14="无效","",IF(C14="",0,C14/$U14*100)) -> 0 | Z14: =IF($V14="无效","",IF(D14="",0,D14/$U14*100)) -> 0.92175133 | AA14: =IF($V14="无效","",IF(E14="",0,E14/$U14*100)) -> 0.21039976 | AB14: =IF($V14="无效","",IF(F14="",0,F14/$U14*100)) -> 0 | AC14: =IF($V14="无效","",IF(G14="",0,G14/$U14*100)) -> 0.81154193 | AD14: =IF($V14="无效","",IF(H14="",0,H14/$U14*100)) -> 0.26049494 | AE14: =IF($V14="无效","",IF(I14="",0,I14/$U14*100)) -> 0.84159904 | ... AK14: =IF($V14="无效","",IF(O14="",0,O14/$U14*100)) -> 0 | AL14: =IF(V14="有效",SUM(X14:AK14),"") -> 100
A15: 11 | B15: 33.59 | D15: 0.21 | E15: 3.51 | F15: 0.71 | G15: 2.69 | I15: 4.93 | J15: 25.39 | K15: 14.61 | L15: 9.38 | M15: 0.37 | P15: 11 | Q15: =IF(ISNUMBER(SEARCH("未风化点",A15)),"未风化点",IF(ISNUMBER(SEARCH("严重风化点",A15)),"严重风化点",IF(ISNUMBER(SEARCH("部位",A15)),"不同部位","普通采样点"))) -> 普通采样点 | R15: =VLOOKUP(P15,表单1_清洗!$A$2:$E$59,3,FALSE) -> 铅钡 | S15: =VLOOKUP(P15,表单1_清洗!$A$2:$E$59,5,FALSE) -> 风化 | T15: =IF(ISNUMBER(SEARCH("未风化点",A15)),"无风化",IF(ISNUMBER(SEARCH("严重风化点",A15)),"风化",S15)) -> 风化 | U15: =SUM(B15:O15) -> 95.39 | V15: =IF(AND(U15>=85,U15<=105),"有效","无效") -> 有效 | W15: =COUNTBLANK(B15:O15)+COUNTIF(B15:O15,0) -> 4 | X15: =IF($V15="无效","",IF(B15="",0,B15/$U15*100)) -> 35.213335 | Y15: =IF($V15="无效","",IF(C15="",0,C15/$U15*100)) -> 0 | Z15: =IF($V15="无效","",IF(D15="",0,D15/$U15*100)) -> 0.22014886 | AA15: =IF($V15="无效","",IF(E15="",0,E15/$U15*100)) -> 3.679631 | AB15: =IF($V15="无效","",IF(F15="",0,F15/$U15*100)) -> 0.74431282 | AC15: =IF($V15="无效","",IF(G15="",0,G15/$U15*100)) -> 2.8200021 | AD15: =IF($V15="无效","",IF(H15="",0,H15/$U15*100)) -> 0 | AE15: =IF($V15="无效","",IF(I15="",0,I15/$U15*100)) -> 5.1682566 | ... AK15: =IF($V15="无效","",IF(O15="",0,O15/$U15*100)) -> 0 | AL15: =IF(V15="有效",SUM(X15:AK15),"") -> 100
A16: 12 | B16: 94.29 | D16: 1.01 | E16: 0.72 | G16: 1.46 | H16: 0.29 | I16: 1.65 | L16: 0.15 | P16: 12 | Q16: =IF(ISNUMBER(SEARCH("未风化点",A16)),"未风化点",IF(ISNUMBER(SEARCH("严重风化点",A16)),"严重风化点",IF(ISNUMBER(SEARCH("部位",A16)),"不同部位","普通采样点"))) -> 普通采样点 | R16: =VLOOKUP(P16,表单1_清洗!$A$2:$E$59,3,FALSE) -> 高钾 | S16: =VLOOKUP(P16,表单1_清洗!$A$2:$E$59,5,FALSE) -> 风化 | T16: =IF(ISNUMBER(SEARCH("未风化点",A16)),"无风化",IF(ISNUMBER(SEARCH("严重风化点",A16)),"风化",S16)) -> 风化 | U16: =SUM(B16:O16) -> 99.57 | V16: =IF(AND(U16>=85,U16<=105),"有效","无效") -> 有效 | W16: =COUNTBLANK(B16:O16)+COUNTIF(B16:O16,0) -> 7 | X16: =IF($V16="无效","",IF(B16="",0,B16/$U16*100)) -> 94.697198 | Y16: =IF($V16="无效","",IF(C16="",0,C16/$U16*100)) -> 0 | Z16: =IF($V16="无效","",IF(D16="",0,D16/$U16*100)) -> 1.0143618 | AA16: =IF($V16="无效","",IF(E16="",0,E16/$U16*100)) -> 0.72310937 | AB16: =IF($V16="无效","",IF(F16="",0,F16/$U16*100)) -> 0 | AC16: =IF($V16="无效","",IF(G16="",0,G16/$U16*100)) -> 1.4663051 | AD16: =IF($V16="无效","",IF(H16="",0,H16/$U16*100)) -> 0.29125239 | AE16: =IF($V16="无效","",IF(I16="",0,I16/$U16*100)) -> 1.6571256 | ... AK16: =IF($V16="无效","",IF(O16="",0,O16/$U16*100)) -> 0 | AL16: =IF(V16="有效",SUM(X16:AK16),"") -> 100
A17: 13 | B17: 59.01 | C17: 2.86 | D17: 12.53 | E17: 8.7 | G17: 6.16 | H17: 2.88 | I17: 4.73 | L17: 1.27 | P17: 13 | Q17: =IF(ISNUMBER(SEARCH("未风化点",A17)),"未风化点",IF(ISNUMBER(SEARCH("严重风化点",A17)),"严重风化点",IF(ISNUMBER(SEARCH("部位",A17)),"不同部位","普通采样点"))) -> 普通采样点 | R17: =VLOOKUP(P17,表单1_清洗!$A$2:$E$59,3,FALSE) -> 高钾 | S17: =VLOOKUP(P17,表单1_清洗!$A$2:$E$59,5,FALSE) -> 无风化 | T17: =IF(ISNUMBER(SEARCH("未风化点",A17)),"无风化",IF(ISNUMBER(SEARCH("严重风化点",A17)),"风化",S17)) -> 无风化 | U17: =SUM(B17:O17) -> 98.14 | V17: =IF(AND(U17>=85,U17<=105),"有效","无效") -> 有效 | W17: =COUNTBLANK(B17:O17)+COUNTIF(B17:O17,0) -> 6 | X17: =IF($V17="无效","",IF(B17="",0,B17/$U17*100)) -> 60.128388 | Y17: =IF($V17="无效","",IF(C17="",0,C17/$U17*100)) -> 2.9142042 | Z17: =IF($V17="无效","",IF(D17="",0,D17/$U17*100)) -> 12.767475 | AA17: =IF($V17="无效","",IF(E17="",0,E17/$U17*100)) -> 8.8648869 | AB17: =IF($V17="无效","",IF(F17="",0,F17/$U17*100)) -> 0 | AC17: =IF($V17="无效","",IF(G17="",0,G17/$U17*100)) -> 6.2767475 | AD17: =IF($V17="无效","",IF(H17="",0,H17/$U17*100)) -> 2.9345832 | AE17: =IF($V17="无效","",IF(I17="",0,I17/$U17*100)) -> 4.8196454 | ... AK17: =IF($V17="无效","",IF(O17="",0,O17/$U17*100)) -> 0 | AL17: =IF(V17="有效",SUM(X17:AK17),"") -> 100
A18: 14 | B18: 62.47 | C18: 3.38 | D18: 12.28 | E18: 8.23 | F18: 0.66 | G18: 9.23 | H18: 0.5 | I18: 0.47 | J18: 1.62 | L18: 0.16 | P18: 14 | Q18: =IF(ISNUMBER(SEARCH("未风化点",A18)),"未风化点",IF(ISNUMBER(SEARCH("严重风化点",A18)),"严重风化点",IF(ISNUMBER(SEARCH("部位",A18)),"不同部位","普通采样点"))) -> 普通采样点 | R18: =VLOOKUP(P18,表单1_清洗!$A$2:$E$59,3,FALSE) -> 高钾 | S18: =VLOOKUP(P18,表单1_清洗!$A$2:$E$59,5,FALSE) -> 无风化 | T18: =IF(ISNUMBER(SEARCH("未风化点",A18)),"无风化",IF(ISNUMBER(SEARCH("严重风化点",A18)),"风化",S18)) -> 无风化 | U18: =SUM(B18:O18) -> 99 | V18: =IF(AND(U18>=85,U18<=105),"有效","无效") -> 有效 | W18: =COUNTBLANK(B18:O18)+COUNTIF(B18:O18,0) -> 4 | X18: =IF($V18="无效","",IF(B18="",0,B18/$U18*100)) -> 63.10101 | Y18: =IF($V18="无效","",IF(C18="",0,C18/$U18*100)) -> 3.4141414 | Z18: =IF($V18="无效","",IF(D18="",0,D18/$U18*100)) -> 12.40404 | AA18: =IF($V18="无效","",IF(E18="",0,E18/$U18*100)) -> 8.3131313 | AB18: =IF($V18="无效","",IF(F18="",0,F18/$U18*100)) -> 0.66666667 | AC18: =IF($V18="无效","",IF(G18="",0,G18/$U18*100)) -> 9.3232323 | AD18: =IF($V18="无效","",IF(H18="",0,H18/$U18*100)) -> 0.50505051 | AE18: =IF($V18="无效","",IF(I18="",0,I18/$U18*100)) -> 0.47474747 | ... AK18: =IF($V18="无效","",IF(O18="",0,O18/$U18*100)) -> 0 | AL18: =IF(V18="有效",SUM(X18:AK18),"") -> 100
A19: 15 | B19: 61.87 | C19: 3.21 | D19: 7.44 | F19: 1.02 | G19: 3.15 | H19: 1.04 | I19: 1.29 | J19: 0.19 | K19: 0 | L19: 0.26 | P19: 15 | Q19: =IF(ISNUMBER(SEARCH("未风化点",A19)),"未风化点",IF(ISNUMBER(SEARCH("严重风化点",A19)),"严重风化点",IF(ISNUMBER(SEARCH("部位",A19)),"不同部位","普通采样点"))) -> 普通采样点 | R19: =VLOOKUP(P19,表单1_清洗!$A$2:$E$59,3,FALSE) -> 高钾 | S19: =VLOOKUP(P19,表单1_清洗!$A$2:$E$59,5,FALSE) -> 无风化 | T19: =IF(ISNUMBER(SEARCH("未风化点",A19)),"无风化",IF(ISNUMBER(SEARCH("严重风化点",A19)),"风化",S19)) -> 无风化 | U19: =SUM(B19:O19) -> 79.47 | V19: =IF(AND(U19>=85,U19<=105),"有效","无效") -> 无效 | W19: =COUNTBLANK(B19:O19)+COUNTIF(B19:O19,0) -> 5 | X19: =IF($V19="无效","",IF(B19="",0,B19/$U19*100)) | Y19: =IF($V19="无效","",IF(C19="",0,C19/$U19*100)) | Z19: =IF($V19="无效","",IF(D19="",0,D19/$U19*100)) | AA19: =IF($V19="无效","",IF(E19="",0,E19/$U19*100)) | AB19: =IF($V19="无效","",IF(F19="",0,F19/$U19*100)) | AC19: =IF($V19="无效","",IF(G19="",0,G19/$U19*100)) | AD19: =IF($V19="无效","",IF(H19="",0,H19/$U19*100)) | AE19: =IF($V19="无效","",IF(I19="",0,I19/$U19*100)) | ... AK19: =IF($V19="无效","",IF(O19="",0,O19/$U19*100)) | AL19: =IF(V19="有效",SUM(X19:AK19),"")
A20: 16 | B20: 65.18 | C20: 2.1 | D20: 14.52 | E20: 8.27 | F20: 0.52 | G20: 6.18 | H20: 0.42 | I20: 1.07 | J20: 0.11 | K20: 0 | M20: 0.04 | P20: 16 | Q20: =IF(ISNUMBER(SEARCH("未风化点",A20)),"未风化点",IF(ISNUMBER(SEARCH("严重风化点",A20)),"严重风化点",IF(ISNUMBER(SEARCH("部位",A20)),"不同部位","普通采样点"))) -> 普通采样点 | R20: =VLOOKUP(P20,表单1_清洗!$A$2:$E$59,3,FALSE) -> 高钾 | S20: =VLOOKUP(P20,表单1_清洗!$A$2:$E$59,5,FALSE) -> 无风化 | T20: =IF(ISNUMBER(SEARCH("未风化点",A20)),"无风化",IF(ISNUMBER(SEARCH("严重风化点",A20)),"风化",S20)) -> 无风化 | U20: =SUM(B20:O20) -> 98.41 | V20: =IF(AND(U20>=85,U20<=105),"有效","无效") -> 有效 | W20: =COUNTBLANK(B20:O20)+COUNTIF(B20:O20,0) -> 4 | X20: =IF($V20="无效","",IF(B20="",0,B20/$U20*100)) -> 66.233106 | Y20: =IF($V20="无效","",IF(C20="",0,C20/$U20*100)) -> 2.1339295 | Z20: =IF($V20="无效","",IF(D20="",0,D20/$U20*100)) -> 14.754598 | AA20: =IF($V20="无效","",IF(E20="",0,E20/$U20*100)) -> 8.4036175 | AB20: =IF($V20="无效","",IF(F20="",0,F20/$U20*100)) -> 0.52840159 | AC20: =IF($V20="无效","",IF(G20="",0,G20/$U20*100)) -> 6.2798496 | AD20: =IF($V20="无效","",IF(H20="",0,H20/$U20*100)) -> 0.4267859 | AE20: =IF($V20="无效","",IF(I20="",0,I20/$U20*100)) -> 1.0872879 | ... AK20: =IF($V20="无效","",IF(O20="",0,O20/$U20*100)) -> 0 | AL20: =IF(V20="有效",SUM(X20:AK20),"") -> 100
A21: 17 | B21: 60.71 | C21: 2.12 | D21: 5.71 | F21: 0.85 | H21: 1.04 | I21: 1.09 | J21: 0.19 | K21: 0 | L21: 0.18 | N21: 0 | P21: 17 | Q21: =IF(ISNUMBER(SEARCH("未风化点",A21)),"未风化点",IF(ISNUMBER(SEARCH("严重风化点",A21)),"严重风化点",IF(ISNUMBER(SEARCH("部位",A21)),"不同部位","普通采样点"))) -> 普通采样点 | R21: =VLOOKUP(P21,表单1_清洗!$A$2:$E$59,3,FALSE) -> 高钾 | S21: =VLOOKUP(P21,表单1_清洗!$A$2:$E$59,5,FALSE) -> 无风化 | T21: =IF(ISNUMBER(SEARCH("未风化点",A21)),"无风化",IF(ISNUMBER(SEARCH("严重风化点",A21)),"风化",S21)) -> 无风化 | U21: =SUM(B21:O21) -> 71.89 | V21: =IF(AND(U21>=85,U21<=105),"有效","无效") -> 无效 | W21: =COUNTBLANK(B21:O21)+COUNTIF(B21:O21,0) -> 6 | X21: =IF($V21="无效","",IF(B21="",0,B21/$U21*100)) | Y21: =IF($V21="无效","",IF(C21="",0,C21/$U21*100)) | Z21: =IF($V21="无效","",IF(D21="",0,D21/$U21*100)) | AA21: =IF($V21="无效","",IF(E21="",0,E21/$U21*100)) | AB21: =IF($V21="无效","",IF(F21="",0,F21/$U21*100)) | AC21: =IF($V21="无效","",IF(G21="",0,G21/$U21*100)) | AD21: =IF($V21="无效","",IF(H21="",0,H21/$U21*100)) | AE21: =IF($V21="无效","",IF(I21="",0,I21/$U21*100)) | ... AK21: =IF($V21="无效","",IF(O21="",0,O21/$U21*100)) | AL21: =IF(V21="有效",SUM(X21:AK21),"")
A22: 18 | B22: 79.46 | D22: 9.42 | F22: 1.53 | G22: 3.05 | L22: 1.36 | M22: 0.07 | N22: 2.36 | P22: 18 | Q22: =IF(ISNUMBER(SEARCH("未风化点",A22)),"未风化点",IF(ISNUMBER(SEARCH("严重风化点",A22)),"严重风化点",IF(ISNUMBER(SEARCH("部位",A22)),"不同部位","普通采样点"))) -> 普通采样点 | R22: =VLOOKUP(P22,表单1_清洗!$A$2:$E$59,3,FALSE) -> 高钾 | S22: =VLOOKUP(P22,表单1_清洗!$A$2:$E$59,5,FALSE) -> 无风化 | T22: =IF(ISNUMBER(SEARCH("未风化点",A22)),"无风化",IF(ISNUMBER(SEARCH("严重风化点",A22)),"风化",S22)) -> 无风化 | U22: =SUM(B22:O22) -> 97.25 | V22: =IF(AND(U22>=85,U22<=105),"有效","无效") -> 有效 | W22: =COUNTBLANK(B22:O22)+COUNTIF(B22:O22,0) -> 7 | X22: =IF($V22="无效","",IF(B22="",0,B22/$U22*100)) -> 81.706941 | Y22: =IF($V22="无效","",IF(C22="",0,C22/$U22*100)) -> 0 | Z22: =IF($V22="无效","",IF(D22="",0,D22/$U22*100)) -> 9.6863753 | AA22: =IF($V22="无效","",IF(E22="",0,E22/$U22*100)) -> 0 | AB22: =IF($V22="无效","",IF(F22="",0,F22/$U22*100)) -> 1.5732648 | AC22: =IF($V22="无效","",IF(G22="",0,G22/$U22*100)) -> 3.1362468 | AD22: =IF($V22="无效","",IF(H22="",0,H22/$U22*100)) -> 0 | AE22: =IF($V22="无效","",IF(I22="",0,I22/$U22*100)) -> 0 | ... AK22: =IF($V22="无效","",IF(O22="",0,O22/$U22*100)) -> 0 | AL22: =IF(V22="有效",SUM(X22:AK22),"") -> 100
A23: 19 | B23: 29.64 | E23: 2.93 | F23: 0.59 | G23: 3.57 | H23: 1.33 | I23: 3.51 | J23: 42.82 | K23: 5.35 | L23: 8.83 | M23: 0.19 | P23: 19 | Q23: =IF(ISNUMBER(SEARCH("未风化点",A23)),"未风化点",IF(ISNUMBER(SEARCH("严重风化点",A23)),"严重风化点",IF(ISNUMBER(SEARCH("部位",A23)),"不同部位","普通采样点"))) -> 普通采样点 | R23: =VLOOKUP(P23,表单1_清洗!$A$2:$E$59,3,FALSE) -> 铅钡 | S23: =VLOOKUP(P23,表单1_清洗!$A$2:$E$59,5,FALSE) -> 风化 | T23: =IF(ISNUMBER(SEARCH("未风化点",A23)),"无风化",IF(ISNUMBER(SEARCH("严重风化点",A23)),"风化",S23)) -> 风化 | U23: =SUM(B23:O23) -> 98.76 | V23: =IF(AND(U23>=85,U23<=105),"有效","无效") -> 有效 | W23: =COUNTBLANK(B23:O23)+COUNTIF(B23:O23,0) -> 4 | X23: =IF($V23="无效","",IF(B23="",0,B23/$U23*100)) -> 30.012151 | Y23: =IF($V23="无效","",IF(C23="",0,C23/$U23*100)) -> 0 | Z23: =IF($V23="无效","",IF(D23="",0,D23/$U23*100)) -> 0 | AA23: =IF($V23="无效","",IF(E23="",0,E23/$U23*100)) -> 2.9667882 | AB23: =IF($V23="无效","",IF(F23="",0,F23/$U23*100)) -> 0.59740786 | AC23: =IF($V23="无效","",IF(G23="",0,G23/$U23*100)) -> 3.6148238 | AD23: =IF($V23="无效","",IF(H23="",0,H23/$U23*100)) -> 1.3466991 | AE23: =IF($V23="无效","",IF(I23="",0,I23/$U23*100)) -> 3.5540705 | ... AK23: =IF($V23="无效","",IF(O23="",0,O23/$U23*100)) -> 0 | AL23: =IF(V23="有效",SUM(X23:AK23),"") -> 100
A24: 20 | B24: 37.36 | D24: 0.71 | G24: 5.45 | H24: 1.51 | I24: 4.78 | J24: 9.3 | K24: 23.55 | L24: 5.75 | P24: 20 | Q24: =IF(ISNUMBER(SEARCH("未风化点",A24)),"未风化点",IF(ISNUMBER(SEARCH("严重风化点",A24)),"严重风化点",IF(ISNUMBER(SEARCH("部位",A24)),"不同部位","普通采样点"))) -> 普通采样点 | R24: =VLOOKUP(P24,表单1_清洗!$A$2:$E$59,3,FALSE) -> 铅钡 | S24: =VLOOKUP(P24,表单1_清洗!$A$2:$E$59,5,FALSE) -> 无风化 | T24: =IF(ISNUMBER(SEARCH("未风化点",A24)),"无风化",IF(ISNUMBER(SEARCH("严重风化点",A24)),"风化",S24)) -> 无风化 | U24: =SUM(B24:O24) -> 88.41 | V24: =IF(AND(U24>=85,U24<=105),"有效","无效") -> 有效 | W24: =COUNTBLANK(B24:O24)+COUNTIF(B24:O24,0) -> 6 | X24: =IF($V24="无效","",IF(B24="",0,B24/$U24*100)) -> 42.257663 | Y24: =IF($V24="无效","",IF(C24="",0,C24/$U24*100)) -> 0 | Z24: =IF($V24="无效","",IF(D24="",0,D24/$U24*100)) -> 0.80307658 | AA24: =IF($V24="无效","",IF(E24="",0,E24/$U24*100)) -> 0 | AB24: =IF($V24="无效","",IF(F24="",0,F24/$U24*100)) -> 0 | AC24: =IF($V24="无效","",IF(G24="",0,G24/$U24*100)) -> 6.164461 | AD24: =IF($V24="无效","",IF(H24="",0,H24/$U24*100)) -> 1.7079516 | AE24: =IF($V24="无效","",IF(I24="",0,I24/$U24*100)) -> 5.4066282 | ... AK24: =IF($V24="无效","",IF(O24="",0,O24/$U24*100)) -> 0 | AL24: =IF(V24="有效",SUM(X24:AK24),"") -> 100
A25: 21 | B25: 76.68 | E25: 4.71 | F25: 1.22 | G25: 6.19 | H25: 2.37 | I25: 3.28 | J25: 1 | K25: 1.97 | L25: 1.1 | P25: 21 | Q25: =IF(ISNUMBER(SEARCH("未风化点",A25)),"未风化点",IF(ISNUMBER(SEARCH("严重风化点",A25)),"严重风化点",IF(ISNUMBER(SEARCH("部位",A25)),"不同部位","普通采样点"))) -> 普通采样点 | R25: =VLOOKUP(P25,表单1_清洗!$A$2:$E$59,3,FALSE) -> 高钾 | S25: =VLOOKUP(P25,表单1_清洗!$A$2:$E$59,5,FALSE) -> 无风化 | T25: =IF(ISNUMBER(SEARCH("未风化点",A25)),"无风化",IF(ISNUMBER(SEARCH("严重风化点",A25)),"风化",S25)) -> 无风化 | U25: =SUM(B25:O25) -> 98.52 | V25: =IF(AND(U25>=85,U25<=105),"有效","无效") -> 有效 | W25: =COUNTBLANK(B25:O25)+COUNTIF(B25:O25,0) -> 5 | X25: =IF($V25="无效","",IF(B25="",0,B25/$U25*100)) -> 77.831912 | Y25: =IF($V25="无效","",IF(C25="",0,C25/$U25*100)) -> 0 | Z25: =IF($V25="无效","",IF(D25="",0,D25/$U25*100)) -> 0 | AA25: =IF($V25="无效","",IF(E25="",0,E25/$U25*100)) -> 4.7807552 | AB25: =IF($V25="无效","",IF(F25="",0,F25/$U25*100)) -> 1.2383272 | AC25: =IF($V25="无效","",IF(G25="",0,G25/$U25*100)) -> 6.2829882 | AD25: =IF($V25="无效","",IF(H25="",0,H25/$U25*100)) -> 2.4056029 | AE25: =IF($V25="无效","",IF(I25="",0,I25/$U25*100)) -> 3.3292732 | ... AK25: =IF($V25="无效","",IF(O25="",0,O25/$U25*100)) -> 0 | AL25: =IF(V25="有效",SUM(X25:AK25),"") -> 100
A26: 22 | B26: 92.35 | D26: 0.74 | E26: 1.66 | F26: 0.64 | G26: 3.5 | H26: 0.35 | I26: 0.55 | L26: 0.21 | P26: 22 | Q26: =IF(ISNUMBER(SEARCH("未风化点",A26)),"未风化点",IF(ISNUMBER(SEARCH("严重风化点",A26)),"严重风化点",IF(ISNUMBER(SEARCH("部位",A26)),"不同部位","普通采样点"))) -> 普通采样点 | R26: =VLOOKUP(P26,表单1_清洗!$A$2:$E$59,3,FALSE) -> 高钾 | S26: =VLOOKUP(P26,表单1_清洗!$A$2:$E$59,5,FALSE) -> 风化 | T26: =IF(ISNUMBER(SEARCH("未风化点",A26)),"无风化",IF(ISNUMBER(SEARCH("严重风化点",A26)),"风化",S26)) -> 风化 | U26: =SUM(B26:O26) -> 100 | V26: =IF(AND(U26>=85,U26<=105),"有效","无效") -> 有效 | W26: =COUNTBLANK(B26:O26)+COUNTIF(B26:O26,0) -> 6 | X26: =IF($V26="无效","",IF(B26="",0,B26/$U26*100)) -> 92.35 | Y26: =IF($V26="无效","",IF(C26="",0,C26/$U26*100)) -> 0 | Z26: =IF($V26="无效","",IF(D26="",0,D26/$U26*100)) -> 0.74 | AA26: =IF($V26="无效","",IF(E26="",0,E26/$U26*100)) -> 1.66 | AB26: =IF($V26="无效","",IF(F26="",0,F26/$U26*100)) -> 0.64 | AC26: =IF($V26="无效","",IF(G26="",0,G26/$U26*100)) -> 3.5 | AD26: =IF($V26="无效","",IF(H26="",0,H26/$U26*100)) -> 0.35 | AE26: =IF($V26="无效","",IF(I26="",0,I26/$U26*100)) -> 0.55 | ... AK26: =IF($V26="无效","",IF(O26="",0,O26/$U26*100)) -> 0 | AL26: =IF(V26="有效",SUM(X26:AK26),"") -> 100
A27: 23未风化点 | B27: 53.79 | C27: 7.92 | E27: 0.5 | F27: 0.71 | G27: 1.42 | I27: 2.99 | J27: 16.98 | K27: 11.86 | M27: 0.33 | P27: 23 | Q27: =IF(ISNUMBER(SEARCH("未风化点",A27)),"未风化点",IF(ISNUMBER(SEARCH("严重风化点",A27)),"严重风化点",IF(ISNUMBER(SEARCH("部位",A27)),"不同部位","普通采样点"))) -> 未风化点 | R27: =VLOOKUP(P27,表单1_清洗!$A$2:$E$59,3,FALSE) -> 铅钡 | S27: =VLOOKUP(P27,表单1_清洗!$A$2:$E$59,5,FALSE) -> 风化 | T27: =IF(ISNUMBER(SEARCH("未风化点",A27)),"无风化",IF(ISNUMBER(SEARCH("严重风化点",A27)),"风化",S27)) -> 无风化 | U27: =SUM(B27:O27) -> 96.5 | V27: =IF(AND(U27>=85,U27<=105),"有效","无效") -> 有效 | W27: =COUNTBLANK(B27:O27)+COUNTIF(B27:O27,0) -> 5 | X27: =IF($V27="无效","",IF(B27="",0,B27/$U27*100)) -> 55.740933 | Y27: =IF($V27="无效","",IF(C27="",0,C27/$U27*100)) -> 8.2072539 | Z27: =IF($V27="无效","",IF(D27="",0,D27/$U27*100)) -> 0 | AA27: =IF($V27="无效","",IF(E27="",0,E27/$U27*100)) -> 0.51813472 | AB27: =IF($V27="无效","",IF(F27="",0,F27/$U27*100)) -> 0.7357513 | AC27: =IF($V27="无效","",IF(G27="",0,G27/$U27*100)) -> 1.4715026 | AD27: =IF($V27="无效","",IF(H27="",0,H27/$U27*100)) -> 0 | AE27: =IF($V27="无效","",IF(I27="",0,I27/$U27*100)) -> 3.0984456 | ... AK27: =IF($V27="无效","",IF(O27="",0,O27/$U27*100)) -> 0 | AL27: =IF(V27="有效",SUM(X27:AK27),"") -> 100
A28: 24 | B28: 31.94 | E28: 0.47 | G28: 1.59 | I28: 8.46 | J28: 29.14 | K28: 26.23 | L28: 0.14 | M28: 0.91 | P28: 24 | Q28: =IF(ISNUMBER(SEARCH("未风化点",A28)),"未风化点",IF(ISNUMBER(SEARCH("严重风化点",A28)),"严重风化点",IF(ISNUMBER(SEARCH("部位",A28)),"不同部位","普通采样点"))) -> 普通采样点 | R28: =VLOOKUP(P28,表单1_清洗!$A$2:$E$59,3,FALSE) -> 铅钡 | S28: =VLOOKUP(P28,表单1_清洗!$A$2:$E$59,5,FALSE) -> 无风化 | T28: =IF(ISNUMBER(SEARCH("未风化点",A28)),"无风化",IF(ISNUMBER(SEARCH("严重风化点",A28)),"风化",S28)) -> 无风化 | U28: =SUM(B28:O28) -> 98.88 | V28: =IF(AND(U28>=85,U28<=105),"有效","无效") -> 有效 | W28: =COUNTBLANK(B28:O28)+COUNTIF(B28:O28,0) -> 6 | X28: =IF($V28="无效","",IF(B28="",0,B28/$U28*100)) -> 32.30178 | Y28: =IF($V28="无效","",IF(C28="",0,C28/$U28*100)) -> 0 | Z28: =IF($V28="无效","",IF(D28="",0,D28/$U28*100)) -> 0 | AA28: =IF($V28="无效","",IF(E28="",0,E28/$U28*100)) -> 0.47532362 | AB28: =IF($V28="无效","",IF(F28="",0,F28/$U28*100)) -> 0 | AC28: =IF($V28="无效","",IF(G28="",0,G28/$U28*100)) -> 1.6080097 | AD28: =IF($V28="无效","",IF(H28="",0,H28/$U28*100)) -> 0 | AE28: =IF($V28="无效","",IF(I28="",0,I28/$U28*100)) -> 8.5558252 | ... AK28: =IF($V28="无效","",IF(O28="",0,O28/$U28*100)) -> 0 | AL28: =IF(V28="有效",SUM(X28:AK28),"") -> 100
A29: 25未风化点 | B29: 50.61 | C29: 2.31 | E29: 0.63 | G29: 1.9 | H29: 1.55 | I29: 1.12 | J29: 31.9 | K29: 6.65 | L29: 0.19 | M29: 0.2 | P29: 25 | Q29: =IF(ISNUMBER(SEARCH("未风化点",A29)),"未风化点",IF(ISNUMBER(SEARCH("严重风化点",A29)),"严重风化点",IF(ISNUMBER(SEARCH("部位",A29)),"不同部位","普通采样点"))) -> 未风化点 | R29: =VLOOKUP(P29,表单1_清洗!$A$2:$E$59,3,FALSE) -> 铅钡 | S29: =VLOOKUP(P29,表单1_清洗!$A$2:$E$59,5,FALSE) -> 风化 | T29: =IF(ISNUMBER(SEARCH("未风化点",A29)),"无风化",IF(ISNUMBER(SEARCH("严重风化点",A29)),"风化",S29)) -> 无风化 | U29: =SUM(B29:O29) -> 97.06 | V29: =IF(AND(U29>=85,U29<=105),"有效","无效") -> 有效 | W29: =COUNTBLANK(B29:O29)+COUNTIF(B29:O29,0) -> 4 | X29: =IF($V29="无效","",IF(B29="",0,B29/$U29*100)) -> 52.143004 | Y29: =IF($V29="无效","",IF(C29="",0,C29/$U29*100)) -> 2.3799712 | Z29: =IF($V29="无效","",IF(D29="",0,D29/$U29*100)) -> 0 | AA29: =IF($V29="无效","",IF(E29="",0,E29/$U29*100)) -> 0.64908304 | AB29: =IF($V29="无效","",IF(F29="",0,F29/$U29*100)) -> 0 | AC29: =IF($V29="无效","",IF(G29="",0,G29/$U29*100)) -> 1.957552 | AD29: =IF($V29="无效","",IF(H29="",0,H29/$U29*100)) -> 1.5969503 | AE29: =IF($V29="无效","",IF(I29="",0,I29/$U29*100)) -> 1.1539254 | ... AK29: =IF($V29="无效","",IF(O29="",0,O29/$U29*100)) -> 0 | AL29: =IF(V29="有效",SUM(X29:AK29),"") -> 100
A30: 26 | B30: 19.79 | E30: 1.44 | G30: 0.7 | I30: 10.57 | J30: 29.53 | K30: 32.25 | L30: 3.13 | M30: 0.45 | O30: 1.96 | P30: 26 | Q30: =IF(ISNUMBER(SEARCH("未风化点",A30)),"未风化点",IF(ISNUMBER(SEARCH("严重风化点",A30)),"严重风化点",IF(ISNUMBER(SEARCH("部位",A30)),"不同部位","普通采样点"))) -> 普通采样点 | R30: =VLOOKUP(P30,表单1_清洗!$A$2:$E$59,3,FALSE) -> 铅钡 | S30: =VLOOKUP(P30,表单1_清洗!$A$2:$E$59,5,FALSE) -> 风化 | T30: =IF(ISNUMBER(SEARCH("未风化点",A30)),"无风化",IF(ISNUMBER(SEARCH("严重风化点",A30)),"风化",S30)) -> 风化 | U30: =SUM(B30:O30) -> 99.82 | V30: =IF(AND(U30>=85,U30<=105),"有效","无效") -> 有效 | W30: =COUNTBLANK(B30:O30)+COUNTIF(B30:O30,0) -> 5 | X30: =IF($V30="无效","",IF(B30="",0,B30/$U30*100)) -> 19.825686 | Y30: =IF($V30="无效","",IF(C30="",0,C30/$U30*100)) -> 0 | Z30: =IF($V30="无效","",IF(D30="",0,D30/$U30*100)) -> 0 | AA30: =IF($V30="无效","",IF(E30="",0,E30/$U30*100)) -> 1.4425967 | AB30: =IF($V30="无效","",IF(F30="",0,F30/$U30*100)) -> 0 | AC30: =IF($V30="无效","",IF(G30="",0,G30/$U30*100)) -> 0.70126227 | AD30: =IF($V30="无效","",IF(H30="",0,H30/$U30*100)) -> 0 | AE30: =IF($V30="无效","",IF(I30="",0,I30/$U30*100)) -> 10.58906 | ... AK30: =IF($V30="无效","",IF(O30="",0,O30/$U30*100)) -> 1.9635344 | AL30: =IF(V30="有效",SUM(X30:AK30),"") -> 100
A31: 26严重风化点 | B31: 3.72 | D31: 0.4 | E31: 3.01 | G31: 1.18 | I31: 3.6 | J31: 29.92 | K31: 35.45 | L31: 6.04 | M31: 0.62 | O31: 15.95 | P31: 26 | Q31: =IF(ISNUMBER(SEARCH("未风化点",A31)),"未风化点",IF(ISNUMBER(SEARCH("严重风化点",A31)),"严重风化点",IF(ISNUMBER(SEARCH("部位",A31)),"不同部位","普通采样点"))) -> 严重风化点 | R31: =VLOOKUP(P31,表单1_清洗!$A$2:$E$59,3,FALSE) -> 铅钡 | S31: =VLOOKUP(P31,表单1_清洗!$A$2:$E$59,5,FALSE) -> 风化 | T31: =IF(ISNUMBER(SEARCH("未风化点",A31)),"无风化",IF(ISNUMBER(SEARCH("严重风化点",A31)),"风化",S31)) -> 风化 | U31: =SUM(B31:O31) -> 99.89 | V31: =IF(AND(U31>=85,U31<=105),"有效","无效") -> 有效 | W31: =COUNTBLANK(B31:O31)+COUNTIF(B31:O31,0) -> 4 | X31: =IF($V31="无效","",IF(B31="",0,B31/$U31*100)) -> 3.7240965 | Y31: =IF($V31="无效","",IF(C31="",0,C31/$U31*100)) -> 0 | Z31: =IF($V31="无效","",IF(D31="",0,D31/$U31*100)) -> 0.40044048 | AA31: =IF($V31="无效","",IF(E31="",0,E31/$U31*100)) -> 3.0133146 | AB31: =IF($V31="无效","",IF(F31="",0,F31/$U31*100)) -> 0 | AC31: =IF($V31="无效","",IF(G31="",0,G31/$U31*100)) -> 1.1812994 | AD31: =IF($V31="无效","",IF(H31="",0,H31/$U31*100)) -> 0 | AE31: =IF($V31="无效","",IF(I31="",0,I31/$U31*100)) -> 3.6039644 | ... AK31: =IF($V31="无效","",IF(O31="",0,O31/$U31*100)) -> 15.967564 | AL31: =IF(V31="有效",SUM(X31:AK31),"") -> 100
A32: 27 | B32: 92.72 | E32: 0.94 | F32: 0.54 | G32: 2.51 | H32: 0.2 | I32: 1.54 | L32: 0.36 | P32: 27 | Q32: =IF(ISNUMBER(SEARCH("未风化点",A32)),"未风化点",IF(ISNUMBER(SEARCH("严重风化点",A32)),"严重风化点",IF(ISNUMBER(SEARCH("部位",A32)),"不同部位","普通采样点"))) -> 普通采样点 | R32: =VLOOKUP(P32,表单1_清洗!$A$2:$E$59,3,FALSE) -> 高钾 | S32: =VLOOKUP(P32,表单1_清洗!$A$2:$E$59,5,FALSE) -> 风化 | T32: =IF(ISNUMBER(SEARCH("未风化点",A32)),"无风化",IF(ISNUMBER(SEARCH("严重风化点",A32)),"风化",S32)) -> 风化 | U32: =SUM(B32:O32) -> 98.81 | V32: =IF(AND(U32>=85,U32<=105),"有效","无效") -> 有效 | W32: =COUNTBLANK(B32:O32)+COUNTIF(B32:O32,0) -> 7 | X32: =IF($V32="无效","",IF(B32="",0,B32/$U32*100)) -> 93.836656 | Y32: =IF($V32="无效","",IF(C32="",0,C32/$U32*100)) -> 0 | Z32: =IF($V32="无效","",IF(D32="",0,D32/$U32*100)) -> 0 | AA32: =IF($V32="无效","",IF(E32="",0,E32/$U32*100)) -> 0.95132072 | AB32: =IF($V32="无效","",IF(F32="",0,F32/$U32*100)) -> 0.54650339 | AC32: =IF($V32="无效","",IF(G32="",0,G32/$U32*100)) -> 2.5402287 | AD32: =IF($V32="无效","",IF(H32="",0,H32/$U32*100)) -> 0.20240866 | AE32: =IF($V32="无效","",IF(I32="",0,I32/$U32*100)) -> 1.5585467 | ... AK32: =IF($V32="无效","",IF(O32="",0,O32/$U32*100)) -> 0 | AL32: =IF(V32="有效",SUM(X32:AK32),"") -> 100
A33: 28未风化点 | B33: 68.08 | D33: 0.26 | E33: 1.34 | F33: 1 | G33: 4.7 | H33: 0.41 | I33: 0.33 | J33: 17.14 | K33: 4.04 | L33: 1.04 | M33: 0.12 | N33: 0.23 | P33: 28 | Q33: =IF(ISNUMBER(SEARCH("未风化点",A33)),"未风化点",IF(ISNUMBER(SEARCH("严重风化点",A33)),"严重风化点",IF(ISNUMBER(SEARCH("部位",A33)),"不同部位","普通采样点"))) -> 未风化点 | R33: =VLOOKUP(P33,表单1_清洗!$A$2:$E$59,3,FALSE) -> 铅钡 | S33: =VLOOKUP(P33,表单1_清洗!$A$2:$E$59,5,FALSE) -> 风化 | T33: =IF(ISNUMBER(SEARCH("未风化点",A33)),"无风化",IF(ISNUMBER(SEARCH("严重风化点",A33)),"风化",S33)) -> 无风化 | U33: =SUM(B33:O33) -> 98.69 | V33: =IF(AND(U33>=85,U33<=105),"有效","无效") -> 有效 | W33: =COUNTBLANK(B33:O33)+COUNTIF(B33:O33,0) -> 2 | X33: =IF($V33="无效","",IF(B33="",0,B33/$U33*100)) -> 68.983686 | Y33: =IF($V33="无效","",IF(C33="",0,C33/$U33*100)) -> 0 | Z33: =IF($V33="无效","",IF(D33="",0,D33/$U33*100)) -> 0.26345121 | AA33: =IF($V33="无效","",IF(E33="",0,E33/$U33*100)) -> 1.357787 | AB33: =IF($V33="无效","",IF(F33="",0,F33/$U33*100)) -> 1.0132739 | AC33: =IF($V33="无效","",IF(G33="",0,G33/$U33*100)) -> 4.7623873 | AD33: =IF($V33="无效","",IF(H33="",0,H33/$U33*100)) -> 0.41544229 | AE33: =IF($V33="无效","",IF(I33="",0,I33/$U33*100)) -> 0.33438038 | ... AK33: =IF($V33="无效","",IF(O33="",0,O33/$U33*100)) -> 0 | AL33: =IF(V33="有效",SUM(X33:AK33),"") -> 100
A34: 29未风化点 | B34: 63.3 | C34: 0.92 | D34: 0.3 | E34: 2.98 | F34: 1.49 | G34: 14.34 | H34: 0.81 | I34: 0.74 | J34: 12.31 | K34: 2.03 | L34: 0.41 | M34: 0.25 | P34: 29 | Q34: =IF(ISNUMBER(SEARCH("未风化点",A34)),"未风化点",IF(ISNUMBER(SEARCH("严重风化点",A34)),"严重风化点",IF(ISNUMBER(SEARCH("部位",A34)),"不同部位","普通采样点"))) -> 未风化点 | R34: =VLOOKUP(P34,表单1_清洗!$A$2:$E$59,3,FALSE) -> 铅钡 | S34: =VLOOKUP(P34,表单1_清洗!$A$2:$E$59,5,FALSE) -> 风化 | T34: =IF(ISNUMBER(SEARCH("未风化点",A34)),"无风化",IF(ISNUMBER(SEARCH("严重风化点",A34)),"风化",S34)) -> 无风化 | U34: =SUM(B34:O34) -> 99.88 | V34: =IF(AND(U34>=85,U34<=105),"有效","无效") -> 有效 | W34: =COUNTBLANK(B34:O34)+COUNTIF(B34:O34,0) -> 2 | X34: =IF($V34="无效","",IF(B34="",0,B34/$U34*100)) -> 63.376051 | Y34: =IF($V34="无效","",IF(C34="",0,C34/$U34*100)) -> 0.92110533 | Z34: =IF($V34="无效","",IF(D34="",0,D34/$U34*100)) -> 0.30036043 | AA34: =IF($V34="无效","",IF(E34="",0,E34/$U34*100)) -> 2.9835803 | AB34: =IF($V34="无效","",IF(F34="",0,F34/$U34*100)) -> 1.4917901 | AC34: =IF($V34="无效","",IF(G34="",0,G34/$U34*100)) -> 14.357229 | AD34: =IF($V34="无效","",IF(H34="",0,H34/$U34*100)) -> 0.81097317 | AE34: =IF($V34="无效","",IF(I34="",0,I34/$U34*100)) -> 0.74088907 | ... AK34: =IF($V34="无效","",IF(O34="",0,O34/$U34*100)) -> 0 | AL34: =IF(V34="有效",SUM(X34:AK34),"") -> 100
